Workbook

Sheet How To Use
A1: DW Invitational 2026 · Backup Scoring Sheet
A2: Use this only if the website is down. It follows the same rules as the dashboard.
A4: ENTERING SCORES
A5: 1. | B5: Open the tab for the round: R1 Watson (Thu), R2 Palmer (Fri), or R3 Nicklaus (Sat).
A6: 2. | B6: Type each player’s GROSS score in the yellow boxes, one box per hole. Leave unplayed holes blank.
A7: 3. | B7: Everything else is automatic: strokes, net scores, Mankles points, team best ball, skins and the Leaderboard.
A8: 4. | B8: A score that looks like a typo (0, or more than 3× par) is blocked, same as the website.
A10: WHAT THE COLORS MEAN
A11: Yellow | B11: Type here (scores). Round 3 also has a yellow “Group · Tee” column for the Saturday pairings.
A12: Blue text | B12: Settings you can change: handicaps on the Players tab, skins pot and team place points on the Leaderboard.
A13: Gold square | B13: Birdie or better. Grey square = double bogey or worse.
A14: Grey text | B14: Working math. Don’t type over it.
A16: THE RULES
A17: Strokes | B17: Everyone strokes off the field low handicap (Frank Barta, 8): your handicap − 8, on the hardest holes first.
A18: R1 & R2 | B18: Team best ball: on each hole, add the two lowest net scores of the three teammates. Teams rank 1–5 → 20 / 15 / 10 / 5 / 0 points.
A19: R3 | B19: Singles net: every player’s net total is ranked across the field. 1st = 15 points, down to 15th = 1 point. Points go to the player’s team.
A20: Ties | B20: Teams or players who tie split the points for the places they share.
A21: Mankles | B21: Each round = handicap + points on gross vs par: eagle or better 8, birdie 4, par 2, bogey 1, double 0, triple or worse −1. Ties on the 3-round total go to the most birdies.
A22: Skins | B22: $180 per round. Lowest net on a hole wins the skin outright; ties = no skin, no carry-overs. The pot is split evenly across the skins won.
A23: R3 groups | B23: After Round 2, the lowest Mankles totals tee off first (10:50 group of 3) and the leaders go last (11:20). Check the Leaderboard and type the groups on the R3 tab.
A25: PHONE TIP
A26: Excel app | B26: Works in the free Excel app on iPhone. Save a copy to OneDrive or iCloud before the trip so it opens without the internet.

Sheet Leaderboard
A1: DW Invitational 2026 · Live Standings
A2: Backup scoring sheet · type scores on the R1 / R2 / R3 tabs and this page updates itself
A3: Skins pot per round | B3: 180
A4: Team place points
A5: 1st place | B5: 20
A6: 2nd place | B6: 15
A7: 3rd place | B7: 10
A8: 4th place | B8: 5
A9: 5th place | B9: 0
A11: Team Standings
A12: Pos | B12: Team | C12: R1 | D12: R2 | E12: R3 | F12: Total
A13: =IF(G43+G44+G45+G46+G47=0,"—",1) -> — | B13: =INDEX($A$43:$A$47,MATCH(LARGE($F$43:$F$47,1),$F$43:$F$47,0)) -> Team 2 | C13: =IF(INDEX($B$43:$B$47,MATCH(LARGE($F$43:$F$47,1),$F$43:$F$47,0))="","—",INDEX($B$43:$B$47,MATCH(LARGE($F$43:$F$47,1),$F$43:$F$47,0))) -> — | D13: =IF(INDEX($C$43:$C$47,MATCH(LARGE($F$43:$F$47,1),$F$43:$F$47,0))="","—",INDEX($C$43:$C$47,MATCH(LARGE($F$43:$F$47,1),$F$43:$F$47,0))) -> — | E13: =IF(INDEX($D$43:$D$47,MATCH(LARGE($F$43:$F$47,1),$F$43:$F$47,0))="","—",INDEX($D$43:$D$47,MATCH(LARGE($F$43:$F$47,1),$F$43:$F$47,0))) -> — | F13: =IF(INDEX($G$43:$G$47,MATCH(LARGE($F$43:$F$47,1),$F$43:$F$47,0)),INDEX($E$43:$E$47,MATCH(LARGE($F$43:$F$47,1),$F$43:$F$47,0)),"—") -> —
A14: =IF(G43+G44+G45+G46+G47=0,"—",2) -> — | B14: =INDEX($A$43:$A$47,MATCH(LARGE($F$43:$F$47,2),$F$43:$F$47,0)) -> Skull it and Pray | C14: =IF(INDEX($B$43:$B$47,MATCH(LARGE($F$43:$F$47,2),$F$43:$F$47,0))="","—",INDEX($B$43:$B$47,MATCH(LARGE($F$43:$F$47,2),$F$43:$F$47,0))) -> — | D14: =IF(INDEX($C$43:$C$47,MATCH(LARGE($F$43:$F$47,2),$F$43:$F$47,0))="","—",INDEX($C$43:$C$47,MATCH(LARGE($F$43:$F$47,2),$F$43:$F$47,0))) -> — | E14: =IF(INDEX($D$43:$D$47,MATCH(LARGE($F$43:$F$47,2),$F$43:$F$47,0))="","—",INDEX($D$43:$D$47,MATCH(LARGE($F$43:$F$47,2),$F$43:$F$47,0))) -> — | F14: =IF(INDEX($G$43:$G$47,MATCH(LARGE($F$43:$F$47,2),$F$43:$F$47,0)),INDEX($E$43:$E$47,MATCH(LARGE($F$43:$F$47,2),$F$43:$F$47,0)),"—") -> —
A15: =IF(G43+G44+G45+G46+G47=0,"—",3) -> — | B15: =INDEX($A$43:$A$47,MATCH(LARGE($F$43:$F$47,3),$F$43:$F$47,0)) -> Team 3 | C15: =IF(INDEX($B$43:$B$47,MATCH(LARGE($F$43:$F$47,3),$F$43:$F$47,0))="","—",INDEX($B$43:$B$47,MATCH(LARGE($F$43:$F$47,3),$F$43:$F$47,0))) -> — | D15: =IF(INDEX($C$43:$C$47,MATCH(LARGE($F$43:$F$47,3),$F$43:$F$47,0))="","—",INDEX($C$43:$C$47,MATCH(LARGE($F$43:$F$47,3),$F$43:$F$47,0))) -> — | E15: =IF(INDEX($D$43:$D$47,MATCH(LARGE($F$43:$F$47,3),$F$43:$F$47,0))="","—",INDEX($D$43:$D$47,MATCH(LARGE($F$43:$F$47,3),$F$43:$F$47,0))) -> — | F15: =IF(INDEX($G$43:$G$47,MATCH(LARGE($F$43:$F$47,3),$F$43:$F$47,0)),INDEX($E$43:$E$47,MATCH(LARGE($F$43:$F$47,3),$F$43:$F$47,0)),"—") -> —
A16: =IF(G43+G44+G45+G46+G47=0,"—",4) -> — | B16: =INDEX($A$43:$A$47,MATCH(LARGE($F$43:$F$47,4),$F$43:$F$47,0)) -> Wydom’s Woodies | C16: =IF(INDEX($B$43:$B$47,MATCH(LARGE($F$43:$F$47,4),$F$43:$F$47,0))="","—",INDEX($B$43:$B$47,MATCH(LARGE($F$43:$F$47,4),$F$43:$F$47,0))) -> — | D16: =IF(INDEX($C$43:$C$47,MATCH(LARGE($F$43:$F$47,4),$F$43:$F$47,0))="","—",INDEX($C$43:$C$47,MATCH(LARGE($F$43:$F$47,4),$F$43:$F$47,0))) -> — | E16: =IF(INDEX($D$43:$D$47,MATCH(LARGE($F$43:$F$47,4),$F$43:$F$47,0))="","—",INDEX($D$43:$D$47,MATCH(LARGE($F$43:$F$47,4),$F$43:$F$47,0))) -> — | F16: =IF(INDEX($G$43:$G$47,MATCH(LARGE($F$43:$F$47,4),$F$43:$F$47,0)),INDEX($E$43:$E$47,MATCH(LARGE($F$43:$F$47,4),$F$43:$F$47,0)),"—") -> —
A17: =IF(G43+G44+G45+G46+G47=0,"—",5) -> — | B17: =INDEX($A$43:$A$47,MATCH(LARGE($F$43:$F$47,5),$F$43:$F$47,0)) -> Putting Balls in the Hole | C17: =IF(INDEX($B$43:$B$47,MATCH(LARGE($F$43:$F$47,5),$F$43:$F$47,0))="","—",INDEX($B$43:$B$47,MATCH(LARGE($F$43:$F$47,5),$F$43:$F$47,0))) -> — | D17: =IF(INDEX($C$43:$C$47,MATCH(LARGE($F$43:$F$47,5),$F$43:$F$47,0))="","—",INDEX($C$43:$C$47,MATCH(LARGE($F$43:$F$47,5),$F$43:$F$47,0))) -> — | E17: =IF(INDEX($D$43:$D$47,MATCH(LARGE($F$43:$F$47,5),$F$43:$F$47,0))="","—",INDEX($D$43:$D$47,MATCH(LARGE($F$43:$F$47,5),$F$43:$F$47,0))) -> — | F17: =IF(INDEX($G$43:$G$47,MATCH(LARGE($F$43:$F$47,5),$F$43:$F$47,0)),INDEX($E$43:$E$47,MATCH(LARGE($F$43:$F$47,5),$F$43:$F$47,0)),"—") -> —
A18: R1 & R2: team best ball (2 lowest nets per hole) → 20/15/10/5/0. R3: singles net → 15…1 per player, to their team.
A20: Individual Mankles · handicap + points per round
A21: Pos | B21: Player | C21: Team | D21: Hcp | E21: R1 | F21: R2 | G21: R3 | H21: Total | I21: Birdies+
A22: =IF(SUM($J$52:$J$66)=0,"—",1) -> — | B22: =INDEX($A$52:$A$66,MATCH(LARGE($I$52:$I$66,1),$I$52:$I$66,0)) -> Frank Barta | C22: =INDEX($B$52:$B$66,MATCH(LARGE($I$52:$I$66,1),$I$52:$I$66,0)) -> Team 2 | D22: =INDEX($C$52:$C$66,MATCH(LARGE($I$52:$I$66,1),$I$52:$I$66,0)) -> 8 | E22: =IF(INDEX($D$52:$D$66,MATCH(LARGE($I$52:$I$66,1),$I$52:$I$66,0))="","—",INDEX($D$52:$D$66,MATCH(LARGE($I$52:$I$66,1),$I$52:$I$66,0))) -> — | F22: =IF(INDEX($E$52:$E$66,MATCH(LARGE($I$52:$I$66,1),$I$52:$I$66,0))="","—",INDEX($E$52:$E$66,MATCH(LARGE($I$52:$I$66,1),$I$52:$I$66,0))) -> — | G22: =IF(INDEX($F$52:$F$66,MATCH(LARGE($I$52:$I$66,1),$I$52:$I$66,0))="","—",INDEX($F$52:$F$66,MATCH(LARGE($I$52:$I$66,1),$I$52:$I$66,0))) -> — | H22: =IF(INDEX($J$52:$J$66,MATCH(LARGE($I$52:$I$66,1),$I$52:$I$66,0))=0,"—",INDEX($G$52:$G$66,MATCH(LARGE($I$52:$I$66,1),$I$52:$I$66,0))) -> — | I22: =INDEX($H$52:$H$66,MATCH(LARGE($I$52:$I$66,1),$I$52:$I$66,0)) -> 0
A23: =IF(SUM($J$52:$J$66)=0,"—",2) -> — | B23: =INDEX($A$52:$A$66,MATCH(LARGE($I$52:$I$66,2),$I$52:$I$66,0)) -> Marc Wydom | C23: =INDEX($B$52:$B$66,MATCH(LARGE($I$52:$I$66,2),$I$52:$I$66,0)) -> Team 2 | D23: =INDEX($C$52:$C$66,MATCH(LARGE($I$52:$I$66,2),$I$52:$I$66,0)) -> 16 | E23: =IF(INDEX($D$52:$D$66,MATCH(LARGE($I$52:$I$66,2),$I$52:$I$66,0))="","—",INDEX($D$52:$D$66,MATCH(LARGE($I$52:$I$66,2),$I$52:$I$66,0))) -> — | F23: =IF(INDEX($E$52:$E$66,MATCH(LARGE($I$52:$I$66,2),$I$52:$I$66,0))="","—",INDEX($E$52:$E$66,MATCH(LARGE($I$52:$I$66,2),$I$52:$I$66,0))) -> — | G23: =IF(INDEX($F$52:$F$66,MATCH(LARGE($I$52:$I$66,2),$I$52:$I$66,0))="","—",INDEX($F$52:$F$66,MATCH(LARGE($I$52:$I$66,2),$I$52:$I$66,0))) -> — | H23: =IF(INDEX($J$52:$J$66,MATCH(LARGE($I$52:$I$66,2),$I$52:$I$66,0))=0,"—",INDEX($G$52:$G$66,MATCH(LARGE($I$52:$I$66,2),$I$52:$I$66,0))) -> — | I23: =INDEX($H$52:$H$66,MATCH(LARGE($I$52:$I$66,2),$I$52:$I$66,0)) -> 0
A24: =IF(SUM($J$52:$J$66)=0,"—",3) -> — | B24: =INDEX($A$52:$A$66,MATCH(LARGE($I$52:$I$66,3),$I$52:$I$66,0)) -> Donnie Muller | C24: =INDEX($B$52:$B$66,MATCH(LARGE($I$52:$I$66,3),$I$52:$I$66,0)) -> Team 2 | D24: =INDEX($C$52:$C$66,MATCH(LARGE($I$52:$I$66,3),$I$52:$I$66,0)) -> 19 | E24: =IF(INDEX($D$52:$D$66,MATCH(LARGE($I$52:$I$66,3),$I$52:$I$66,0))="","—",INDEX($D$52:$D$66,MATCH(LARGE($I$52:$I$66,3),$I$52:$I$66,0))) -> — | F24: =IF(INDEX($E$52:$E$66,MATCH(LARGE($I$52:$I$66,3),$I$52:$I$66,0))="","—",INDEX($E$52:$E$66,MATCH(LARGE($I$52:$I$66,3),$I$52:$I$66,0))) -> — | G24: =IF(INDEX($F$52:$F$66,MATCH(LARGE($I$52:$I$66,3),$I$52:$I$66,0))="","—",INDEX($F$52:$F$66,MATCH(LARGE($I$52:$I$66,3),$I$52:$I$66,0))) -> — | H24: =IF(INDEX($J$52:$J$66,MATCH(LARGE($I$52:$I$66,3),$I$52:$I$66,0))=0,"—",INDEX($G$52:$G$66,MATCH(LARGE($I$52:$I$66,3),$I$52:$I$66,0))) -> — | I24: =INDEX($H$52:$H$66,MATCH(LARGE($I$52:$I$66,3),$I$52:$I$66,0)) -> 0
A25: =IF(SUM($J$52:$J$66)=0,"—",4) -> — | B25: =INDEX($A$52:$A$66,MATCH(LARGE($I$52:$I$66,4),$I$52:$I$66,0)) -> Tommy Duncan | C25: =INDEX($B$52:$B$66,MATCH(LARGE($I$52:$I$66,4),$I$52:$I$66,0)) -> Skull it and Pray | D25: =INDEX($C$52:$C$66,MATCH(LARGE($I$52:$I$66,4),$I$52:$I$66,0)) -> 24 | E25: =IF(INDEX($D$52:$D$66,MATCH(LARGE($I$52:$I$66,4),$I$52:$I$66,0))="","—",INDEX($D$52:$D$66,MATCH(LARGE($I$52:$I$66,4),$I$52:$I$66,0))) -> — | F25: =IF(INDEX($E$52:$E$66,MATCH(LARGE($I$52:$I$66,4),$I$52:$I$66,0))="","—",INDEX($E$52:$E$66,MATCH(LARGE($I$52:$I$66,4),$I$52:$I$66,0))) -> — | G25: =IF(INDEX($F$52:$F$66,MATCH(LARGE($I$52:$I$66,4),$I$52:$I$66,0))="","—",INDEX($F$52:$F$66,MATCH(LARGE($I$52:$I$66,4),$I$52:$I$66,0))) -> — | H25: =IF(INDEX($J$52:$J$66,MATCH(LARGE($I$52:$I$66,4),$I$52:$I$66,0))=0,"—",INDEX($G$52:$G$66,MATCH(LARGE($I$52:$I$66,4),$I$52:$I$66,0))) -> — | I25: =INDEX($H$52:$H$66,MATCH(LARGE($I$52:$I$66,4),$I$52:$I$66,0)) -> 0
A26: =IF(SUM($J$52:$J$66)=0,"—",5) -> — | B26: =INDEX($A$52:$A$66,MATCH(LARGE($I$52:$I$66,5),$I$52:$I$66,0)) -> Jason Kimbo | C26: =INDEX($B$52:$B$66,MATCH(LARGE($I$52:$I$66,5),$I$52:$I$66,0)) -> Skull it and Pray | D26: =INDEX($C$52:$C$66,MATCH(LARGE($I$52:$I$66,5),$I$52:$I$66,0)) -> 17 | E26: =IF(INDEX($D$52:$D$66,MATCH(LARGE($I$52:$I$66,5),$I$52:$I$66,0))="","—",INDEX($D$52:$D$66,MATCH(LARGE($I$52:$I$66,5),$I$52:$I$66,0))) -> — | F26: =IF(INDEX($E$52:$E$66,MATCH(LARGE($I$52:$I$66,5),$I$52:$I$66,0))="","—",INDEX($E$52:$E$66,MATCH(LARGE($I$52:$I$66,5),$I$52:$I$66,0))) -> — | G26: =IF(INDEX($F$52:$F$66,MATCH(LARGE($I$52:$I$66,5),$I$52:$I$66,0))="","—",INDEX($F$52:$F$66,MATCH(LARGE($I$52:$I$66,5),$I$52:$I$66,0))) -> — | H26: =IF(INDEX($J$52:$J$66,MATCH(LARGE($I$52:$I$66,5),$I$52:$I$66,0))=0,"—",INDEX($G$52:$G$66,MATCH(LARGE($I$52:$I$66,5),$I$52:$I$66,0))) -> — | I26: =INDEX($H$52:$H$66,MATCH(LARGE($I$52:$I$66,5),$I$52:$I$66,0)) -> 0
A27: =IF(SUM($J$52:$J$66)=0,"—",6) -> — | B27: =INDEX($A$52:$A$66,MATCH(LARGE($I$52:$I$66,6),$I$52:$I$66,0)) -> Spencer Friend | C27: =INDEX($B$52:$B$66,MATCH(LARGE($I$52:$I$66,6),$I$52:$I$66,0)) -> Skull it and Pray | D27: =INDEX($C$52:$C$66,MATCH(LARGE($I$52:$I$66,6),$I$52:$I$66,0)) -> 9 | E27: =IF(INDEX($D$52:$D$66,MATCH(LARGE($I$52:$I$66,6),$I$52:$I$66,0))="","—",INDEX($D$52:$D$66,MATCH(LARGE($I$52:$I$66,6),$I$52:$I$66,0))) -> — | F27: =IF(INDEX($E$52:$E$66,MATCH(LARGE($I$52:$I$66,6),$I$52:$I$66,0))="","—",INDEX($E$52:$E$66,MATCH(LARGE($I$52:$I$66,6),$I$52:$I$66,0))) -> — | G27: =IF(INDEX($F$52:$F$66,MATCH(LARGE($I$52:$I$66,6),$I$52:$I$66,0))="","—",INDEX($F$52:$F$66,MATCH(LARGE($I$52:$I$66,6),$I$52:$I$66,0))) -> — | H27: =IF(INDEX($J$52:$J$66,MATCH(LARGE($I$52:$I$66,6),$I$52:$I$66,0))=0,"—",INDEX($G$52:$G$66,MATCH(LARGE($I$52:$I$66,6),$I$52:$I$66,0))) -> — | I27: =INDEX($H$52:$H$66,MATCH(LARGE($I$52:$I$66,6),$I$52:$I$66,0)) -> 0
A28: =IF(SUM($J$52:$J$66)=0,"—",7) -> — | B28: =INDEX($A$52:$A$66,MATCH(LARGE($I$52:$I$66,7),$I$52:$I$66,0)) -> Ben Young | C28: =INDEX($B$52:$B$66,MATCH(LARGE($I$52:$I$66,7),$I$52:$I$66,0)) -> Team 3 | D28: =INDEX($C$52:$C$66,MATCH(LARGE($I$52:$I$66,7),$I$52:$I$66,0)) -> 18 | E28: =IF(INDEX($D$52:$D$66,MATCH(LARGE($I$52:$I$66,7),$I$52:$I$66,0))="","—",INDEX($D$52:$D$66,MATCH(LARGE($I$52:$I$66,7),$I$52:$I$66,0))) -> — | F28: =IF(INDEX($E$52:$E$66,MATCH(LARGE($I$52:$I$66,7),$I$52:$I$66,0))="","—",INDEX($E$52:$E$66,MATCH(LARGE($I$52:$I$66,7),$I$52:$I$66,0))) -> — | G28: =IF(INDEX($F$52:$F$66,MATCH(LARGE($I$52:$I$66,7),$I$52:$I$66,0))="","—",INDEX($F$52:$F$66,MATCH(LARGE($I$52:$I$66,7),$I$52:$I$66,0))) -> — | H28: =IF(INDEX($J$52:$J$66,MATCH(LARGE($I$52:$I$66,7),$I$52:$I$66,0))=0,"—",INDEX($G$52:$G$66,MATCH(LARGE($I$52:$I$66,7),$I$52:$I$66,0))) -> — | I28: =INDEX($H$52:$H$66,MATCH(LARGE($I$52:$I$66,7),$I$52:$I$66,0)) -> 0
A29: =IF(SUM($J$52:$J$66)=0,"—",8) -> — | B29: =INDEX($A$52:$A$66,MATCH(LARGE($I$52:$I$66,8),$I$52:$I$66,0)) -> Justin Conrad | C29: =INDEX($B$52:$B$66,MATCH(LARGE($I$52:$I$66,8),$I$52:$I$66,0)) -> Team 3 | D29: =INDEX($C$52:$C$66,MATCH(LARGE($I$52:$I$66,8),$I$52:$I$66,0)) -> 30 | E29: =IF(INDEX($D$52:$D$66,MATCH(LARGE($I$52:$I$66,8),$I$52:$I$66,0))="","—",INDEX($D$52:$D$66,MATCH(LARGE($I$52:$I$66,8),$I$52:$I$66,0))) -> — | F29: =IF(INDEX($E$52:$E$66,MATCH(LARGE($I$52:$I$66,8),$I$52:$I$66,0))="","—",INDEX($E$52:$E$66,MATCH(LARGE($I$52:$I$66,8),$I$52:$I$66,0))) -> — | G29: =IF(INDEX($F$52:$F$66,MATCH(LARGE($I$52:$I$66,8),$I$52:$I$66,0))="","—",INDEX($F$52:$F$66,MATCH(LARGE($I$52:$I$66,8),$I$52:$I$66,0))) -> — | H29: =IF(INDEX($J$52:$J$66,MATCH(LARGE($I$52:$I$66,8),$I$52:$I$66,0))=0,"—",INDEX($G$52:$G$66,MATCH(LARGE($I$52:$I$66,8),$I$52:$I$66,0))) -> — | I29: =INDEX($H$52:$H$66,MATCH(LARGE($I$52:$I$66,8),$I$52:$I$66,0)) -> 0
A30: =IF(SUM($J$52:$J$66)=0,"—",9) -> — | B30: =INDEX($A$52:$A$66,MATCH(LARGE($I$52:$I$66,9),$I$52:$I$66,0)) -> Shawn McMaster | C30: =INDEX($B$52:$B$66,MATCH(LARGE($I$52:$I$66,9),$I$52:$I$66,0)) -> Team 3 | D30: =INDEX($C$52:$C$66,MATCH(LARGE($I$52:$I$66,9),$I$52:$I$66,0)) -> 19 | E30: =IF(INDEX($D$52:$D$66,MATCH(LARGE($I$52:$I$66,9),$I$52:$I$66,0))="","—",INDEX($D$52:$D$66,MATCH(LARGE($I$52:$I$66,9),$I$52:$I$66,0))) -> — | F30: =IF(INDEX($E$52:$E$66,MATCH(LARGE($I$52:$I$66,9),$I$52:$I$66,0))="","—",INDEX($E$52:$E$66,MATCH(LARGE($I$52:$I$66,9),$I$52:$I$66,0))) -> — | G30: =IF(INDEX($F$52:$F$66,MATCH(LARGE($I$52:$I$66,9),$I$52:$I$66,0))="","—",INDEX($F$52:$F$66,MATCH(LARGE($I$52:$I$66,9),$I$52:$I$66,0))) -> — | H30: =IF(INDEX($J$52:$J$66,MATCH(LARGE($I$52:$I$66,9),$I$52:$I$66,0))=0,"—",INDEX($G$52:$G$66,MATCH(LARGE($I$52:$I$66,9),$I$52:$I$66,0))) -> — | I30: =INDEX($H$52:$H$66,MATCH(LARGE($I$52:$I$66,9),$I$52:$I$66,0)) -> 0
A31: =IF(SUM($J$52:$J$66)=0,"—",10) -> — | B31: =INDEX($A$52:$A$66,MATCH(LARGE($I$52:$I$66,10),$I$52:$I$66,0)) -> Ian Dempsey | C31: =INDEX($B$52:$B$66,MATCH(LARGE($I$52:$I$66,10),$I$52:$I$66,0)) -> Wydom’s Woodies | D31: =INDEX($C$52:$C$66,MATCH(LARGE($I$52:$I$66,10),$I$52:$I$66,0)) -> 21 | E31: =IF(INDEX($D$52:$D$66,MATCH(LARGE($I$52:$I$66,10),$I$52:$I$66,0))="","—",INDEX($D$52:$D$66,MATCH(LARGE($I$52:$I$66,10),$I$52:$I$66,0))) -> — | F31: =IF(INDEX($E$52:$E$66,MATCH(LARGE($I$52:$I$66,10),$I$52:$I$66,0))="","—",INDEX($E$52:$E$66,MATCH(LARGE($I$52:$I$66,10),$I$52:$I$66,0))) -> — | G31: =IF(INDEX($F$52:$F$66,MATCH(LARGE($I$52:$I$66,10),$I$52:$I$66,0))="","—",INDEX($F$52:$F$66,MATCH(LARGE($I$52:$I$66,10),$I$52:$I$66,0))) -> — | H31: =IF(INDEX($J$52:$J$66,MATCH(LARGE($I$52:$I$66,10),$I$52:$I$66,0))=0,"—",INDEX($G$52:$G$66,MATCH(LARGE($I$52:$I$66,10),$I$52:$I$66,0))) -> — | I31: =INDEX($H$52:$H$66,MATCH(LARGE($I$52:$I$66,10),$I$52:$I$66,0)) -> 0
A32: =IF(SUM($J$52:$J$66)=0,"—",11) -> — | B32: =INDEX($A$52:$A$66,MATCH(LARGE($I$52:$I$66,11),$I$52:$I$66,0)) -> Nick Roy | C32: =INDEX($B$52:$B$66,MATCH(LARGE($I$52:$I$66,11),$I$52:$I$66,0)) -> Wydom’s Woodies | D32: =INDEX($C$52:$C$66,MATCH(LARGE($I$52:$I$66,11),$I$52:$I$66,0)) -> 21 | E32: =IF(INDEX($D$52:$D$66,MATCH(LARGE($I$52:$I$66,11),$I$52:$I$66,0))="","—",INDEX($D$52:$D$66,MATCH(LARGE($I$52:$I$66,11),$I$52:$I$66,0))) -> — | F32: =IF(INDEX($E$52:$E$66,MATCH(LARGE($I$52:$I$66,11),$I$52:$I$66,0))="","—",INDEX($E$52:$E$66,MATCH(LARGE($I$52:$I$66,11),$I$52:$I$66,0))) -> — | G32: =IF(INDEX($F$52:$F$66,MATCH(LARGE($I$52:$I$66,11),$I$52:$I$66,0))="","—",INDEX($F$52:$F$66,MATCH(LARGE($I$52:$I$66,11),$I$52:$I$66,0))) -> — | H32: =IF(INDEX($J$52:$J$66,MATCH(LARGE($I$52:$I$66,11),$I$52:$I$66,0))=0,"—",INDEX($G$52:$G$66,MATCH(LARGE($I$52:$I$66,11),$I$52:$I$66,0))) -> — | I32: =INDEX($H$52:$H$66,MATCH(LARGE($I$52:$I$66,11),$I$52:$I$66,0)) -> 0
A33: =IF(SUM($J$52:$J$66)=0,"—",12) -> — | B33: =INDEX($A$52:$A$66,MATCH(LARGE($I$52:$I$66,12),$I$52:$I$66,0)) -> Henry Holst | C33: =INDEX($B$52:$B$66,MATCH(LARGE($I$52:$I$66,12),$I$52:$I$66,0)) -> Wydom’s Woodies | D33: =INDEX($C$52:$C$66,MATCH(LARGE($I$52:$I$66,12),$I$52:$I$66,0)) -> 19 | E33: =IF(INDEX($D$52:$D$66,MATCH(LARGE($I$52:$I$66,12),$I$52:$I$66,0))="","—",INDEX($D$52:$D$66,MATCH(LARGE($I$52:$I$66,12),$I$52:$I$66,0))) -> — | F33: =IF(INDEX($E$52:$E$66,MATCH(LARGE($I$52:$I$66,12),$I$52:$I$66,0))="","—",INDEX($E$52:$E$66,MATCH(LARGE($I$52:$I$66,12),$I$52:$I$66,0))) -> — | G33: =IF(INDEX($F$52:$F$66,MATCH(LARGE($I$52:$I$66,12),$I$52:$I$66,0))="","—",INDEX($F$52:$F$66,MATCH(LARGE($I$52:$I$66,12),$I$52:$I$66,0))) -> — | H33: =IF(INDEX($J$52:$J$66,MATCH(LARGE($I$52:$I$66,12),$I$52:$I$66,0))=0,"—",INDEX($G$52:$G$66,MATCH(LARGE($I$52:$I$66,12),$I$52:$I$66,0))) -> — | I33: =INDEX($H$52:$H$66,MATCH(LARGE($I$52:$I$66,12),$I$52:$I$66,0)) -> 0
A34: =IF(SUM($J$52:$J$66)=0,"—",13) -> — | B34: =INDEX($A$52:$A$66,MATCH(LARGE($I$52:$I$66,13),$I$52:$I$66,0)) -> Chad Stone | C34: =INDEX($B$52:$B$66,MATCH(LARGE($I$52:$I$66,13),$I$52:$I$66,0)) -> Putting Balls in the Hole | D34: =INDEX($C$52:$C$66,MATCH(LARGE($I$52:$I$66,13),$I$52:$I$66,0)) -> 23 | E34: =IF(INDEX($D$52:$D$66,MATCH(LARGE($I$52:$I$66,13),$I$52:$I$66,0))="","—",INDEX($D$52:$D$66,MATCH(LARGE($I$52:$I$66,13),$I$52:$I$66,0))) -> — | F34: =IF(INDEX($E$52:$E$66,MATCH(LARGE($I$52:$I$66,13),$I$52:$I$66,0))="","—",INDEX($E$52:$E$66,MATCH(LARGE($I$52:$I$66,13),$I$52:$I$66,0))) -> — | G34: =IF(INDEX($F$52:$F$66,MATCH(LARGE($I$52:$I$66,13),$I$52:$I$66,0))="","—",INDEX($F$52:$F$66,MATCH(LARGE($I$52:$I$66,13),$I$52:$I$66,0))) -> — | H34: =IF(INDEX($J$52:$J$66,MATCH(LARGE($I$52:$I$66,13),$I$52:$I$66,0))=0,"—",INDEX($G$52:$G$66,MATCH(LARGE($I$52:$I$66,13),$I$52:$I$66,0))) -> — | I34: =INDEX($H$52:$H$66,MATCH(LARGE($I$52:$I$66,13),$I$52:$I$66,0)) -> 0
A35: =IF(SUM($J$52:$J$66)=0,"—",14) -> — | B35: =INDEX($A$52:$A$66,MATCH(LARGE($I$52:$I$66,14),$I$52:$I$66,0)) -> Tom Devine | C35: =INDEX($B$52:$B$66,MATCH(LARGE($I$52:$I$66,14),$I$52:$I$66,0)) -> Putting Balls in the Hole | D35: =INDEX($C$52:$C$66,MATCH(LARGE($I$52:$I$66,14),$I$52:$I$66,0)) -> 17 | E35: =IF(INDEX($D$52:$D$66,MATCH(LARGE($I$52:$I$66,14),$I$52:$I$66,0))="","—",INDEX($D$52:$D$66,MATCH(LARGE($I$52:$I$66,14),$I$52:$I$66,0))) -> — | F35: =IF(INDEX($E$52:$E$66,MATCH(LARGE($I$52:$I$66,14),$I$52:$I$66,0))="","—",INDEX($E$52:$E$66,MATCH(LARGE($I$52:$I$66,14),$I$52:$I$66,0))) -> — | G35: =IF(INDEX($F$52:$F$66,MATCH(LARGE($I$52:$I$66,14),$I$52:$I$66,0))="","—",INDEX($F$52:$F$66,MATCH(LARGE($I$52:$I$66,14),$I$52:$I$66,0))) -> — | H35: =IF(INDEX($J$52:$J$66,MATCH(LARGE($I$52:$I$66,14),$I$52:$I$66,0))=0,"—",INDEX($G$52:$G$66,MATCH(LARGE($I$52:$I$66,14),$I$52:$I$66,0))) -> — | I35: =INDEX($H$52:$H$66,MATCH(LARGE($I$52:$I$66,14),$I$52:$I$66,0)) -> 0
A36: =IF(SUM($J$52:$J$66)=0,"—",15) -> — | B36: =INDEX($A$52:$A$66,MATCH(LARGE($I$52:$I$66,15),$I$52:$I$66,0)) -> Mike Warenda | C36: =INDEX($B$52:$B$66,MATCH(LARGE($I$52:$I$66,15),$I$52:$I$66,0)) -> Putting Balls in the Hole | D36: =INDEX($C$52:$C$66,MATCH(LARGE($I$52:$I$66,15),$I$52:$I$66,0)) -> 21 | E36: =IF(INDEX($D$52:$D$66,MATCH(LARGE($I$52:$I$66,15),$I$52:$I$66,0))="","—",INDEX($D$52:$D$66,MATCH(LARGE($I$52:$I$66,15),$I$52:$I$66,0))) -> — | F36: =IF(INDEX($E$52:$E$66,MATCH(LARGE($I$52:$I$66,15),$I$52:$I$66,0))="","—",INDEX($E$52:$E$66,MATCH(LARGE($I$52:$I$66,15),$I$52:$I$66,0))) -> — | G36: =IF(INDEX($F$52:$F$66,MATCH(LARGE($I$52:$I$66,15),$I$52:$I$66,0))="","—",INDEX($F$52:$F$66,MATCH(LARGE($I$52:$I$66,15),$I$52:$I$66,0))) -> — | H36: =IF(INDEX($J$52:$J$66,MATCH(LARGE($I$52:$I$66,15),$I$52:$I$66,0))=0,"—",INDEX($G$52:$G$66,MATCH(LARGE($I$52:$I$66,15),$I$52:$I$66,0))) -> — | I36: =INDEX($H$52:$H$66,MATCH(LARGE($I$52:$I$66,15),$I$52:$I$66,0)) -> 0
A37: Each round = handicap + Mankles points. Ties on total go to the most birdies (or better) across all rounds.
A39: — Working rows below feed the tables above. Don’t type here. —
A41: Team totals (working rows — the sorted table is above)
A42: Team | B42: R1 | C42: R2 | D42: R3 | E42: Total | F42: Sort key | G42: Any round done
A43: =Players!$F$5 -> Team 2 | B43: ='R1 Watson'!Z83 | C43: ='R2 Palmer'!Z83 | D43: =IF(COUNTIFS('R3 Nicklaus'!$B$8:$B$22,A43,'R3 Nicklaus'!$AE$8:$AE$22,">=0")=0,"",SUMIF('R3 Nicklaus'!$B$8:$B$22,A43,'R3 Nicklaus'!$AE$8:$AE$22)) | E43: =SUM(B43:D43) -> 0 | F43: =E43+(10-0)/1000 -> 0.01 | G43: =COUNT(B43:D43)>0 -> FALSE
A44: =Players!$F$6 -> Skull it and Pray | B44: ='R1 Watson'!Z84 | C44: ='R2 Palmer'!Z84 | D44: =IF(COUNTIFS('R3 Nicklaus'!$B$8:$B$22,A44,'R3 Nicklaus'!$AE$8:$AE$22,">=0")=0,"",SUMIF('R3 Nicklaus'!$B$8:$B$22,A44,'R3 Nicklaus'!$AE$8:$AE$22)) | E44: =SUM(B44:D44) -> 0 | F44: =E44+(10-1)/1000 -> 0.009 | G44: =COUNT(B44:D44)>0 -> FALSE
...

Sheet Skins
A1: Skins · $180 per round
A2: Lowest net score on a hole wins it outright · ties = no skin · no carry-overs · pot split across skins won
A4: Player | B4: R1 skins | C4: R1 $ | D4: R2 skins | E4: R2 $ | F4: R3 skins | G4: R3 $ | H4: Total skins | I4: Total $
A5: =Players!$A$5 -> Frank Barta | B5: =COUNTIF('R1 Watson'!$F$24:$W$24,A5) -> 0 | C5: =B5*'R1 Watson'!$I$25 -> 0 | D5: =COUNTIF('R2 Palmer'!$F$24:$W$24,A5) -> 0 | E5: =D5*'R2 Palmer'!$I$25 -> 0 | F5: =COUNTIF('R3 Nicklaus'!$F$24:$W$24,A5) -> 0 | G5: =F5*'R3 Nicklaus'!$I$25 -> 0 | H5: =B5+D5+F5 -> 0 | I5: =C5+E5+G5 -> 0
A6: =Players!$A$6 -> Marc Wydom | B6: =COUNTIF('R1 Watson'!$F$24:$W$24,A6) -> 0 | C6: =B6*'R1 Watson'!$I$25 -> 0 | D6: =COUNTIF('R2 Palmer'!$F$24:$W$24,A6) -> 0 | E6: =D6*'R2 Palmer'!$I$25 -> 0 | F6: =COUNTIF('R3 Nicklaus'!$F$24:$W$24,A6) -> 0 | G6: =F6*'R3 Nicklaus'!$I$25 -> 0 | H6: =B6+D6+F6 -> 0 | I6: =C6+E6+G6 -> 0
A7: =Players!$A$7 -> Donnie Muller | B7: =COUNTIF('R1 Watson'!$F$24:$W$24,A7) -> 0 | C7: =B7*'R1 Watson'!$I$25 -> 0 | D7: =COUNTIF('R2 Palmer'!$F$24:$W$24,A7) -> 0 | E7: =D7*'R2 Palmer'!$I$25 -> 0 | F7: =COUNTIF('R3 Nicklaus'!$F$24:$W$24,A7) -> 0 | G7: =F7*'R3 Nicklaus'!$I$25 -> 0 | H7: =B7+D7+F7 -> 0 | I7: =C7+E7+G7 -> 0
A8: =Players!$A$8 -> Tommy Duncan | B8: =COUNTIF('R1 Watson'!$F$24:$W$24,A8) -> 0 | C8: =B8*'R1 Watson'!$I$25 -> 0 | D8: =COUNTIF('R2 Palmer'!$F$24:$W$24,A8) -> 0 | E8: =D8*'R2 Palmer'!$I$25 -> 0 | F8: =COUNTIF('R3 Nicklaus'!$F$24:$W$24,A8) -> 0 | G8: =F8*'R3 Nicklaus'!$I$25 -> 0 | H8: =B8+D8+F8 -> 0 | I8: =C8+E8+G8 -> 0
A9: =Players!$A$9 -> Jason Kimbo | B9: =COUNTIF('R1 Watson'!$F$24:$W$24,A9) -> 0 | C9: =B9*'R1 Watson'!$I$25 -> 0 | D9: =COUNTIF('R2 Palmer'!$F$24:$W$24,A9) -> 0 | E9: =D9*'R2 Palmer'!$I$25 -> 0 | F9: =COUNTIF('R3 Nicklaus'!$F$24:$W$24,A9) -> 0 | G9: =F9*'R3 Nicklaus'!$I$25 -> 0 | H9: =B9+D9+F9 -> 0 | I9: =C9+E9+G9 -> 0
A10: =Players!$A$10 -> Spencer Friend | B10: =COUNTIF('R1 Watson'!$F$24:$W$24,A10) -> 0 | C10: =B10*'R1 Watson'!$I$25 -> 0 | D10: =COUNTIF('R2 Palmer'!$F$24:$W$24,A10) -> 0 | E10: =D10*'R2 Palmer'!$I$25 -> 0 | F10: =COUNTIF('R3 Nicklaus'!$F$24:$W$24,A10) -> 0 | G10: =F10*'R3 Nicklaus'!$I$25 -> 0 | H10: =B10+D10+F10 -> 0 | I10: =C10+E10+G10 -> 0
A11: =Players!$A$11 -> Ben Young | B11: =COUNTIF('R1 Watson'!$F$24:$W$24,A11) -> 0 | C11: =B11*'R1 Watson'!$I$25 -> 0 | D11: =COUNTIF('R2 Palmer'!$F$24:$W$24,A11) -> 0 | E11: =D11*'R2 Palmer'!$I$25 -> 0 | F11: =COUNTIF('R3 Nicklaus'!$F$24:$W$24,A11) -> 0 | G11: =F11*'R3 Nicklaus'!$I$25 -> 0 | H11: =B11+D11+F11 -> 0 | I11: =C11+E11+G11 -> 0
A12: =Players!$A$12 -> Justin Conrad | B12: =COUNTIF('R1 Watson'!$F$24:$W$24,A12) -> 0 | C12: =B12*'R1 Watson'!$I$25 -> 0 | D12: =COUNTIF('R2 Palmer'!$F$24:$W$24,A12) -> 0 | E12: =D12*'R2 Palmer'!$I$25 -> 0 | F12: =COUNTIF('R3 Nicklaus'!$F$24:$W$24,A12) -> 0 | G12: =F12*'R3 Nicklaus'!$I$25 -> 0 | H12: =B12+D12+F12 -> 0 | I12: =C12+E12+G12 -> 0
A13: =Players!$A$13 -> Shawn McMaster | B13: =COUNTIF('R1 Watson'!$F$24:$W$24,A13) -> 0 | C13: =B13*'R1 Watson'!$I$25 -> 0 | D13: =COUNTIF('R2 Palmer'!$F$24:$W$24,A13) -> 0 | E13: =D13*'R2 Palmer'!$I$25 -> 0 | F13: =COUNTIF('R3 Nicklaus'!$F$24:$W$24,A13) -> 0 | G13: =F13*'R3 Nicklaus'!$I$25 -> 0 | H13: =B13+D13+F13 -> 0 | I13: =C13+E13+G13 -> 0
A14: =Players!$A$14 -> Ian Dempsey | B14: =COUNTIF('R1 Watson'!$F$24:$W$24,A14) -> 0 | C14: =B14*'R1 Watson'!$I$25 -> 0 | D14: =COUNTIF('R2 Palmer'!$F$24:$W$24,A14) -> 0 | E14: =D14*'R2 Palmer'!$I$25 -> 0 | F14: =COUNTIF('R3 Nicklaus'!$F$24:$W$24,A14) -> 0 | G14: =F14*'R3 Nicklaus'!$I$25 -> 0 | H14: =B14+D14+F14 -> 0 | I14: =C14+E14+G14 -> 0
A15: =Players!$A$15 -> Nick Roy | B15: =COUNTIF('R1 Watson'!$F$24:$W$24,A15) -> 0 | C15: =B15*'R1 Watson'!$I$25 -> 0 | D15: =COUNTIF('R2 Palmer'!$F$24:$W$24,A15) -> 0 | E15: =D15*'R2 Palmer'!$I$25 -> 0 | F15: =COUNTIF('R3 Nicklaus'!$F$24:$W$24,A15) -> 0 | G15: =F15*'R3 Nicklaus'!$I$25 -> 0 | H15: =B15+D15+F15 -> 0 | I15: =C15+E15+G15 -> 0
A16: =Players!$A$16 -> Henry Holst | B16: =COUNTIF('R1 Watson'!$F$24:$W$24,A16) -> 0 | C16: =B16*'R1 Watson'!$I$25 -> 0 | D16: =COUNTIF('R2 Palmer'!$F$24:$W$24,A16) -> 0 | E16: =D16*'R2 Palmer'!$I$25 -> 0 | F16: =COUNTIF('R3 Nicklaus'!$F$24:$W$24,A16) -> 0 | G16: =F16*'R3 Nicklaus'!$I$25 -> 0 | H16: =B16+D16+F16 -> 0 | I16: =C16+E16+G16 -> 0
A17: =Players!$A$17 -> Chad Stone | B17: =COUNTIF('R1 Watson'!$F$24:$W$24,A17) -> 0 | C17: =B17*'R1 Watson'!$I$25 -> 0 | D17: =COUNTIF('R2 Palmer'!$F$24:$W$24,A17) -> 0 | E17: =D17*'R2 Palmer'!$I$25 -> 0 | F17: =COUNTIF('R3 Nicklaus'!$F$24:$W$24,A17) -> 0 | G17: =F17*'R3 Nicklaus'!$I$25 -> 0 | H17: =B17+D17+F17 -> 0 | I17: =C17+E17+G17 -> 0
A18: =Players!$A$18 -> Tom Devine | B18: =COUNTIF('R1 Watson'!$F$24:$W$24,A18) -> 0 | C18: =B18*'R1 Watson'!$I$25 -> 0 | D18: =COUNTIF('R2 Palmer'!$F$24:$W$24,A18) -> 0 | E18: =D18*'R2 Palmer'!$I$25 -> 0 | F18: =COUNTIF('R3 Nicklaus'!$F$24:$W$24,A18) -> 0 | G18: =F18*'R3 Nicklaus'!$I$25 -> 0 | H18: =B18+D18+F18 -> 0 | I18: =C18+E18+G18 -> 0
A19: =Players!$A$19 -> Mike Warenda | B19: =COUNTIF('R1 Watson'!$F$24:$W$24,A19) -> 0 | C19: =B19*'R1 Watson'!$I$25 -> 0 | D19: =COUNTIF('R2 Palmer'!$F$24:$W$24,A19) -> 0 | E19: =D19*'R2 Palmer'!$I$25 -> 0 | F19: =COUNTIF('R3 Nicklaus'!$F$24:$W$24,A19) -> 0 | G19: =F19*'R3 Nicklaus'!$I$25 -> 0 | H19: =B19+D19+F19 -> 0 | I19: =C19+E19+G19 -> 0
A20: Total | B20: =SUM(B5:B19) -> 0 | C20: =SUM(C5:C19) -> 0 | D20: =SUM(D5:D19) -> 0 | E20: =SUM(E5:E19) -> 0 | F20: =SUM(F5:F19) -> 0 | G20: =SUM(G5:G19) -> 0 | H20: =SUM(H5:H19) -> 0 | I20: =SUM(I5:I19) -> 0
A22: A hole only counts once all 15 players have a score on it. Hole-by-hole winners are under each scorecard on the R1 / R2 / R3 tabs.

Sheet R1 Watson
A1: Round I · Tom Watson — Scorecard
A2: Thursday, Nov 5 · Tom Watson · Gold/Blue combo · 71.7/131 tees · par 72
E4: Hole | F4: 1 | G4: 2 | H4: 3 | I4: 4 | J4: 5 | K4: 6 | L4: 7 | M4: 8 | N4: 9 | O4: 10 | P4: 11 | Q4: 12 | R4: 13 | S4: 14 | T4: 15 | U4: 16 | V4: 17 | W4: 18
E5: Par | F5: 5 | G5: 4 | H5: 3 | I5: 4 | J5: 4 | K5: 4 | L5: 3 | M5: 5 | N5: 4 | O5: 4 | P5: 4 | Q5: 3 | R5: 4 | S5: 5 | T5: 3 | U5: 4 | V5: 5 | W5: 4 | X5: =SUM(F5:W5) -> 72
E6: Hole hcp | F6: 5 | G6: 9 | H6: 17 | I6: 1 | J6: 3 | K6: 15 | L6: 11 | M6: 7 | N6: 13 | O6: 2 | P6: 10 | Q6: 16 | R6: 14 | S6: 18 | T6: 12 | U6: 4 | V6: 8 | W6: 6
A7: Player | B7: Team | C7: Hcp | D7: Strokes | E7: Group · Tee | F7: 1 | G7: 2 | H7: 3 | I7: 4 | J7: 5 | K7: 6 | L7: 7 | M7: 8 | N7: 9 | O7: 10 | P7: 11 | Q7: 12 | R7: 13 | S7: 14 | T7: 15 | U7: 16 | V7: 17 | W7: 18 | X7: Gross | Y7: Holes | Z7: Net | AA7: Mankles pts | AB7: Mankles round | AC7: Birdies+
A8: =Players!$A$5 -> Frank Barta | B8: =Players!$B$5 -> Team 2 | C8: =Players!$C$5 -> 8 | D8: =Players!$D$5 -> 0 | E8: Grp 3 · 11:20 AM | X8: =IF(COUNT(F8:W8)=0,"",SUM(F8:W8)) | Y8: =COUNT(F8:W8) -> 0 | Z8: =IF(COUNT(F8:W8)=0,"",SUM(F46:W46)) | AA8: =IF(COUNT(F8:W8)=0,"",SUM(F64:W64)) | AB8: =IF(COUNT(F8:W8)=0,"",C8+AA8) | AC8: =COUNTIF(F64:W64,">=4") -> 0
A9: =Players!$A$6 -> Marc Wydom | B9: =Players!$B$6 -> Team 2 | C9: =Players!$C$6 -> 16 | D9: =Players!$D$6 -> 8 | E9: Grp 3 · 11:20 AM | X9: =IF(COUNT(F9:W9)=0,"",SUM(F9:W9)) | Y9: =COUNT(F9:W9) -> 0 | Z9: =IF(COUNT(F9:W9)=0,"",SUM(F47:W47)) | AA9: =IF(COUNT(F9:W9)=0,"",SUM(F65:W65)) | AB9: =IF(COUNT(F9:W9)=0,"",C9+AA9) | AC9: =COUNTIF(F65:W65,">=4") -> 0
A10: =Players!$A$7 -> Donnie Muller | B10: =Players!$B$7 -> Team 2 | C10: =Players!$C$7 -> 19 | D10: =Players!$D$7 -> 11 | E10: Grp 3 · 11:20 AM | X10: =IF(COUNT(F10:W10)=0,"",SUM(F10:W10)) | Y10: =COUNT(F10:W10) -> 0 | Z10: =IF(COUNT(F10:W10)=0,"",SUM(F48:W48)) | AA10: =IF(COUNT(F10:W10)=0,"",SUM(F66:W66)) | AB10: =IF(COUNT(F10:W10)=0,"",C10+AA10) | AC10: =COUNTIF(F66:W66,">=4") -> 0
A11: =Players!$A$8 -> Tommy Duncan | B11: =Players!$B$8 -> Skull it and Pray | C11: =Players!$C$8 -> 24 | D11: =Players!$D$8 -> 16 | E11: Grp 3 · 11:20 AM | X11: =IF(COUNT(F11:W11)=0,"",SUM(F11:W11)) | Y11: =COUNT(F11:W11) -> 0 | Z11: =IF(COUNT(F11:W11)=0,"",SUM(F49:W49)) | AA11: =IF(COUNT(F11:W11)=0,"",SUM(F67:W67)) | AB11: =IF(COUNT(F11:W11)=0,"",C11+AA11) | AC11: =COUNTIF(F67:W67,">=4") -> 0
A12: =Players!$A$9 -> Jason Kimbo | B12: =Players!$B$9 -> Skull it and Pray | C12: =Players!$C$9 -> 17 | D12: =Players!$D$9 -> 9 | E12: Grp 4 · 11:30 AM | X12: =IF(COUNT(F12:W12)=0,"",SUM(F12:W12)) | Y12: =COUNT(F12:W12) -> 0 | Z12: =IF(COUNT(F12:W12)=0,"",SUM(F50:W50)) | AA12: =IF(COUNT(F12:W12)=0,"",SUM(F68:W68)) | AB12: =IF(COUNT(F12:W12)=0,"",C12+AA12) | AC12: =COUNTIF(F68:W68,">=4") -> 0
A13: =Players!$A$10 -> Spencer Friend | B13: =Players!$B$10 -> Skull it and Pray | C13: =Players!$C$10 -> 9 | D13: =Players!$D$10 -> 1 | E13: Grp 1 · 11:00 AM | X13: =IF(COUNT(F13:W13)=0,"",SUM(F13:W13)) | Y13: =COUNT(F13:W13) -> 0 | Z13: =IF(COUNT(F13:W13)=0,"",SUM(F51:W51)) | AA13: =IF(COUNT(F13:W13)=0,"",SUM(F69:W69)) | AB13: =IF(COUNT(F13:W13)=0,"",C13+AA13) | AC13: =COUNTIF(F69:W69,">=4") -> 0
A14: =Players!$A$11 -> Ben Young | B14: =Players!$B$11 -> Team 3 | C14: =Players!$C$11 -> 18 | D14: =Players!$D$11 -> 10 | E14: Grp 2 · 11:10 AM | X14: =IF(COUNT(F14:W14)=0,"",SUM(F14:W14)) | Y14: =COUNT(F14:W14) -> 0 | Z14: =IF(COUNT(F14:W14)=0,"",SUM(F52:W52)) | AA14: =IF(COUNT(F14:W14)=0,"",SUM(F70:W70)) | AB14: =IF(COUNT(F14:W14)=0,"",C14+AA14) | AC14: =COUNTIF(F70:W70,">=4") -> 0
A15: =Players!$A$12 -> Justin Conrad | B15: =Players!$B$12 -> Team 3 | C15: =Players!$C$12 -> 30 | D15: =Players!$D$12 -> 22 | E15: Grp 2 · 11:10 AM | X15: =IF(COUNT(F15:W15)=0,"",SUM(F15:W15)) | Y15: =COUNT(F15:W15) -> 0 | Z15: =IF(COUNT(F15:W15)=0,"",SUM(F53:W53)) | AA15: =IF(COUNT(F15:W15)=0,"",SUM(F71:W71)) | AB15: =IF(COUNT(F15:W15)=0,"",C15+AA15) | AC15: =COUNTIF(F71:W71,">=4") -> 0
A16: =Players!$A$13 -> Shawn McMaster | B16: =Players!$B$13 -> Team 3 | C16: =Players!$C$13 -> 19 | D16: =Players!$D$13 -> 11 | E16: Grp 2 · 11:10 AM | X16: =IF(COUNT(F16:W16)=0,"",SUM(F16:W16)) | Y16: =COUNT(F16:W16) -> 0 | Z16: =IF(COUNT(F16:W16)=0,"",SUM(F54:W54)) | AA16: =IF(COUNT(F16:W16)=0,"",SUM(F72:W72)) | AB16: =IF(COUNT(F16:W16)=0,"",C16+AA16) | AC16: =COUNTIF(F72:W72,">=4") -> 0
A17: =Players!$A$14 -> Ian Dempsey | B17: =Players!$B$14 -> Wydom’s Woodies | C17: =Players!$C$14 -> 21 | D17: =Players!$D$14 -> 13 | E17: Grp 1 · 11:00 AM | X17: =IF(COUNT(F17:W17)=0,"",SUM(F17:W17)) | Y17: =COUNT(F17:W17) -> 0 | Z17: =IF(COUNT(F17:W17)=0,"",SUM(F55:W55)) | AA17: =IF(COUNT(F17:W17)=0,"",SUM(F73:W73)) | AB17: =IF(COUNT(F17:W17)=0,"",C17+AA17) | AC17: =COUNTIF(F73:W73,">=4") -> 0
A18: =Players!$A$15 -> Nick Roy | B18: =Players!$B$15 -> Wydom’s Woodies | C18: =Players!$C$15 -> 21 | D18: =Players!$D$15 -> 13 | E18: Grp 2 · 11:10 AM | X18: =IF(COUNT(F18:W18)=0,"",SUM(F18:W18)) | Y18: =COUNT(F18:W18) -> 0 | Z18: =IF(COUNT(F18:W18)=0,"",SUM(F56:W56)) | AA18: =IF(COUNT(F18:W18)=0,"",SUM(F74:W74)) | AB18: =IF(COUNT(F18:W18)=0,"",C18+AA18) | AC18: =COUNTIF(F74:W74,">=4") -> 0
A19: =Players!$A$16 -> Henry Holst | B19: =Players!$B$16 -> Wydom’s Woodies | C19: =Players!$C$16 -> 19 | D19: =Players!$D$16 -> 11 | E19: Grp 1 · 11:00 AM | X19: =IF(COUNT(F19:W19)=0,"",SUM(F19:W19)) | Y19: =COUNT(F19:W19) -> 0 | Z19: =IF(COUNT(F19:W19)=0,"",SUM(F57:W57)) | AA19: =IF(COUNT(F19:W19)=0,"",SUM(F75:W75)) | AB19: =IF(COUNT(F19:W19)=0,"",C19+AA19) | AC19: =COUNTIF(F75:W75,">=4") -> 0
A20: =Players!$A$17 -> Chad Stone | B20: =Players!$B$17 -> Putting Balls in the Hole | C20: =Players!$C$17 -> 23 | D20: =Players!$D$17 -> 15 | E20: Grp 4 · 11:30 AM | X20: =IF(COUNT(F20:W20)=0,"",SUM(F20:W20)) | Y20: =COUNT(F20:W20) -> 0 | Z20: =IF(COUNT(F20:W20)=0,"",SUM(F58:W58)) | AA20: =IF(COUNT(F20:W20)=0,"",SUM(F76:W76)) | AB20: =IF(COUNT(F20:W20)=0,"",C20+AA20) | AC20: =COUNTIF(F76:W76,">=4") -> 0
A21: =Players!$A$18 -> Tom Devine | B21: =Players!$B$18 -> Putting Balls in the Hole | C21: =Players!$C$18 -> 17 | D21: =Players!$D$18 -> 9 | E21: Grp 4 · 11:30 AM | X21: =IF(COUNT(F21:W21)=0,"",SUM(F21:W21)) | Y21: =COUNT(F21:W21) -> 0 | Z21: =IF(COUNT(F21:W21)=0,"",SUM(F59:W59)) | AA21: =IF(COUNT(F21:W21)=0,"",SUM(F77:W77)) | AB21: =IF(COUNT(F21:W21)=0,"",C21+AA21) | AC21: =COUNTIF(F77:W77,">=4") -> 0
A22: =Players!$A$19 -> Mike Warenda | B22: =Players!$B$19 -> Putting Balls in the Hole | C22: =Players!$C$19 -> 21 | D22: =Players!$D$19 -> 13 | E22: Grp 4 · 11:30 AM | X22: =IF(COUNT(F22:W22)=0,"",SUM(F22:W22)) | Y22: =COUNT(F22:W22) -> 0 | Z22: =IF(COUNT(F22:W22)=0,"",SUM(F60:W60)) | AA22: =IF(COUNT(F22:W22)=0,"",SUM(F78:W78)) | AB22: =IF(COUNT(F22:W22)=0,"",C22+AA22) | AC22: =COUNTIF(F78:W78,">=4") -> 0
E24: Skin winner | F24: =IF(COUNT(F46:F60)<15,"",IF(COUNTIF(F46:F60,MIN(F46:F60))>1,"tie",INDEX($A$8:$A$22,MATCH(MIN(F46:F60),F46:F60,0)))) | G24: =IF(COUNT(G46:G60)<15,"",IF(COUNTIF(G46:G60,MIN(G46:G60))>1,"tie",INDEX($A$8:$A$22,MATCH(MIN(G46:G60),G46:G60,0)))) | H24: =IF(COUNT(H46:H60)<15,"",IF(COUNTIF(H46:H60,MIN(H46:H60))>1,"tie",INDEX($A$8:$A$22,MATCH(MIN(H46:H60),H46:H60,0)))) | I24: =IF(COUNT(I46:I60)<15,"",IF(COUNTIF(I46:I60,MIN(I46:I60))>1,"tie",INDEX($A$8:$A$22,MATCH(MIN(I46:I60),I46:I60,0)))) | J24: =IF(COUNT(J46:J60)<15,"",IF(COUNTIF(J46:J60,MIN(J46:J60))>1,"tie",INDEX($A$8:$A$22,MATCH(MIN(J46:J60),J46:J60,0)))) | K24: =IF(COUNT(K46:K60)<15,"",IF(COUNTIF(K46:K60,MIN(K46:K60))>1,"tie",INDEX($A$8:$A$22,MATCH(MIN(K46:K60),K46:K60,0)))) | L24: =IF(COUNT(L46:L60)<15,"",IF(COUNTIF(L46:L60,MIN(L46:L60))>1,"tie",INDEX($A$8:$A$22,MATCH(MIN(L46:L60),L46:L60,0)))) | M24: =IF(COUNT(M46:M60)<15,"",IF(COUNTIF(M46:M60,MIN(M46:M60))>1,"tie",INDEX($A$8:$A$22,MATCH(MIN(M46:M60),M46:M60,0)))) | ... W24: =IF(COUNT(W46:W60)<15,"",IF(COUNTIF(W46:W60,MIN(W46:W60))>1,"tie",INDEX($A$8:$A$22,MATCH(MIN(W46:W60),W46:W60,0))))
E25: Skins won | F25: =COUNTIF(F24:W24,"?*")-COUNTIF(F24:W24,"tie") -> 0 | H25: $ per skin | I25: =IF(F25=0,0,Leaderboard!$B$3/F25) -> 0
A27: Handicap strokes on each hole (automatic)
A28: =A8 -> Frank Barta | F28: =INT($D8/18)+IF(F$6<=MOD($D8,18),1,0) -> 0 | G28: =INT($D8/18)+IF(G$6<=MOD($D8,18),1,0) -> 0 | H28: =INT($D8/18)+IF(H$6<=MOD($D8,18),1,0) -> 0 | I28: =INT($D8/18)+IF(I$6<=MOD($D8,18),1,0) -> 0 | J28: =INT($D8/18)+IF(J$6<=MOD($D8,18),1,0) -> 0 | K28: =INT($D8/18)+IF(K$6<=MOD($D8,18),1,0) -> 0 | L28: =INT($D8/18)+IF(L$6<=MOD($D8,18),1,0) -> 0 | M28: =INT($D8/18)+IF(M$6<=MOD($D8,18),1,0) -> 0 | ... W28: =INT($D8/18)+IF(W$6<=MOD($D8,18),1,0) -> 0
A29: =A9 -> Marc Wydom | F29: =INT($D9/18)+IF(F$6<=MOD($D9,18),1,0) -> 1 | G29: =INT($D9/18)+IF(G$6<=MOD($D9,18),1,0) -> 0 | H29: =INT($D9/18)+IF(H$6<=MOD($D9,18),1,0) -> 0 | I29: =INT($D9/18)+IF(I$6<=MOD($D9,18),1,0) -> 1 | J29: =INT($D9/18)+IF(J$6<=MOD($D9,18),1,0) -> 1 | K29: =INT($D9/18)+IF(K$6<=MOD($D9,18),1,0) -> 0 | L29: =INT($D9/18)+IF(L$6<=MOD($D9,18),1,0) -> 0 | M29: =INT($D9/18)+IF(M$6<=MOD($D9,18),1,0) -> 1 | ... W29: =INT($D9/18)+IF(W$6<=MOD($D9,18),1,0) -> 1
A30: =A10 -> Donnie Muller | F30: =INT($D10/18)+IF(F$6<=MOD($D10,18),1,0) -> 1 | G30: =INT($D10/18)+IF(G$6<=MOD($D10,18),1,0) -> 1 | H30: =INT($D10/18)+IF(H$6<=MOD($D10,18),1,0) -> 0 | I30: =INT($D10/18)+IF(I$6<=MOD($D10,18),1,0) -> 1 | J30: =INT($D10/18)+IF(J$6<=MOD($D10,18),1,0) -> 1 | K30: =INT($D10/18)+IF(K$6<=MOD($D10,18),1,0) -> 0 | L30: =INT($D10/18)+IF(L$6<=MOD($D10,18),1,0) -> 1 | M30: =INT($D10/18)+IF(M$6<=MOD($D10,18),1,0) -> 1 | ... W30: =INT($D10/18)+IF(W$6<=MOD($D10,18),1,0) -> 1
A31: =A11 -> Tommy Duncan | F31: =INT($D11/18)+IF(F$6<=MOD($D11,18),1,0) -> 1 | G31: =INT($D11/18)+IF(G$6<=MOD($D11,18),1,0) -> 1 | H31: =INT($D11/18)+IF(H$6<=MOD($D11,18),1,0) -> 0 | I31: =INT($D11/18)+IF(I$6<=MOD($D11,18),1,0) -> 1 | J31: =INT($D11/18)+IF(J$6<=MOD($D11,18),1,0) -> 1 | K31: =INT($D11/18)+IF(K$6<=MOD($D11,18),1,0) -> 1 | L31: =INT($D11/18)+IF(L$6<=MOD($D11,18),1,0) -> 1 | M31: =INT($D11/18)+IF(M$6<=MOD($D11,18),1,0) -> 1 | ... W31: =INT($D11/18)+IF(W$6<=MOD($D11,18),1,0) -> 1
A32: =A12 -> Jason Kimbo | F32: =INT($D12/18)+IF(F$6<=MOD($D12,18),1,0) -> 1 | G32: =INT($D12/18)+IF(G$6<=MOD($D12,18),1,0) -> 1 | H32: =INT($D12/18)+IF(H$6<=MOD($D12,18),1,0) -> 0 | I32: =INT($D12/18)+IF(I$6<=MOD($D12,18),1,0) -> 1 | J32: =INT($D12/18)+IF(J$6<=MOD($D12,18),1,0) -> 1 | K32: =INT($D12/18)+IF(K$6<=MOD($D12,18),1,0) -> 0 | L32: =INT($D12/18)+IF(L$6<=MOD($D12,18),1,0) -> 0 | M32: =INT($D12/18)+IF(M$6<=MOD($D12,18),1,0) -> 1 | ... W32: =INT($D12/18)+IF(W$6<=MOD($D12,18),1,0) -> 1
A33: =A13 -> Spencer Friend | F33: =INT($D13/18)+IF(F$6<=MOD($D13,18),1,0) -> 0 | G33: =INT($D13/18)+IF(G$6<=MOD($D13,18),1,0) -> 0 | H33: =INT($D13/18)+IF(H$6<=MOD($D13,18),1,0) -> 0 | I33: =INT($D13/18)+IF(I$6<=MOD($D13,18),1,0) -> 1 | J33: =INT($D13/18)+IF(J$6<=MOD($D13,18),1,0) -> 0 | K33: =INT($D13/18)+IF(K$6<=MOD($D13,18),1,0) -> 0 | L33: =INT($D13/18)+IF(L$6<=MOD($D13,18),1,0) -> 0 | M33: =INT($D13/18)+IF(M$6<=MOD($D13,18),1,0) -> 0 | ... W33: =INT($D13/18)+IF(W$6<=MOD($D13,18),1,0) -> 0
A34: =A14 -> Ben Young | F34: =INT($D14/18)+IF(F$6<=MOD($D14,18),1,0) -> 1 | G34: =INT($D14/18)+IF(G$6<=MOD($D14,18),1,0) -> 1 | H34: =INT($D14/18)+IF(H$6<=MOD($D14,18),1,0) -> 0 | I34: =INT($D14/18)+IF(I$6<=MOD($D14,18),1,0) -> 1 | J34: =INT($D14/18)+IF(J$6<=MOD($D14,18),1,0) -> 1 | K34: =INT($D14/18)+IF(K$6<=MOD($D14,18),1,0) -> 0 | L34: =INT($D14/18)+IF(L$6<=MOD($D14,18),1,0) -> 0 | M34: =INT($D14/18)+IF(M$6<=MOD($D14,18),1,0) -> 1 | ... W34: =INT($D14/18)+IF(W$6<=MOD($D14,18),1,0) -> 1
A35: =A15 -> Justin Conrad | F35: =INT($D15/18)+IF(F$6<=MOD($D15,18),1,0) -> 1 | G35: =INT($D15/18)+IF(G$6<=MOD($D15,18),1,0) -> 1 | H35: =INT($D15/18)+IF(H$6<=MOD($D15,18),1,0) -> 1 | I35: =INT($D15/18)+IF(I$6<=MOD($D15,18),1,0) -> 2 | J35: =INT($D15/18)+IF(J$6<=MOD($D15,18),1,0) -> 2 | K35: =INT($D15/18)+IF(K$6<=MOD($D15,18),1,0) -> 1 | L35: =INT($D15/18)+IF(L$6<=MOD($D15,18),1,0) -> 1 | M35: =INT($D15/18)+IF(M$6<=MOD($D15,18),1,0) -> 1 | ... W35: =INT($D15/18)+IF(W$6<=MOD($D15,18),1,0) -> 1
A36: =A16 -> Shawn McMaster | F36: =INT($D16/18)+IF(F$6<=MOD($D16,18),1,0) -> 1 | G36: =INT($D16/18)+IF(G$6<=MOD($D16,18),1,0) -> 1 | H36: =INT($D16/18)+IF(H$6<=MOD($D16,18),1,0) -> 0 | I36: =INT($D16/18)+IF(I$6<=MOD($D16,18),1,0) -> 1 | J36: =INT($D16/18)+IF(J$6<=MOD($D16,18),1,0) -> 1 | K36: =INT($D16/18)+IF(K$6<=MOD($D16,18),1,0) -> 0 | L36: =INT($D16/18)+IF(L$6<=MOD($D16,18),1,0) -> 1 | M36: =INT($D16/18)+IF(M$6<=MOD($D16,18),1,0) -> 1 | ... W36: =INT($D16/18)+IF(W$6<=MOD($D16,18),1,0) -> 1
A37: =A17 -> Ian Dempsey | F37: =INT($D17/18)+IF(F$6<=MOD($D17,18),1,0) -> 1 | G37: =INT($D17/18)+IF(G$6<=MOD($D17,18),1,0) -> 1 | H37: =INT($D17/18)+IF(H$6<=MOD($D17,18),1,0) -> 0 | I37: =INT($D17/18)+IF(I$6<=MOD($D17,18),1,0) -> 1 | J37: =INT($D17/18)+IF(J$6<=MOD($D17,18),1,0) -> 1 | K37: =INT($D17/18)+IF(K$6<=MOD($D17,18),1,0) -> 0 | L37: =INT($D17/18)+IF(L$6<=MOD($D17,18),1,0) -> 1 | M37: =INT($D17/18)+IF(M$6<=MOD($D17,18),1,0) -> 1 | ... W37: =INT($D17/18)+IF(W$6<=MOD($D17,18),1,0) -> 1
A38: =A18 -> Nick Roy | F38: =INT($D18/18)+IF(F$6<=MOD($D18,18),1,0) -> 1 | G38: =INT($D18/18)+IF(G$6<=MOD($D18,18),1,0) -> 1 | H38: =INT($D18/18)+IF(H$6<=MOD($D18,18),1,0) -> 0 | I38: =INT($D18/18)+IF(I$6<=MOD($D18,18),1,0) -> 1 | J38: =INT($D18/18)+IF(J$6<=MOD($D18,18),1,0) -> 1 | K38: =INT($D18/18)+IF(K$6<=MOD($D18,18),1,0) -> 0 | L38: =INT($D18/18)+IF(L$6<=MOD($D18,18),1,0) -> 1 | M38: =INT($D18/18)+IF(M$6<=MOD($D18,18),1,0) -> 1 | ... W38: =INT($D18/18)+IF(W$6<=MOD($D18,18),1,0) -> 1
A39: =A19 -> Henry Holst | F39: =INT($D19/18)+IF(F$6<=MOD($D19,18),1,0) -> 1 | G39: =INT($D19/18)+IF(G$6<=MOD($D19,18),1,0) -> 1 | H39: =INT($D19/18)+IF(H$6<=MOD($D19,18),1,0) -> 0 | I39: =INT($D19/18)+IF(I$6<=MOD($D19,18),1,0) -> 1 | J39: =INT($D19/18)+IF(J$6<=MOD($D19,18),1,0) -> 1 | K39: =INT($D19/18)+IF(K$6<=MOD($D19,18),1,0) -> 0 | L39: =INT($D19/18)+IF(L$6<=MOD($D19,18),1,0) -> 1 | M39: =INT($D19/18)+IF(M$6<=MOD($D19,18),1,0) -> 1 | ... W39: =INT($D19/18)+IF(W$6<=MOD($D19,18),1,0) -> 1
... A42: =A22 -> Mike Warenda | F42: =INT($D22/18)+IF(F$6<=MOD($D22,18),1,0) -> 1 | G42: =INT($D22/18)+IF(G$6<=MOD($D22,18),1,0) -> 1 | H42: =INT($D22/18)+IF(H$6<=MOD($D22,18),1,0) -> 0 | I42: =INT($D22/18)+IF(I$6<=MOD($D22,18),1,0) -> 1 | J42: =INT($D22/18)+IF(J$6<=MOD($D22,18),1,0) -> 1 | K42: =INT($D22/18)+IF(K$6<=MOD($D22,18),1,0) -> 0 | L42: =INT($D22/18)+IF(L$6<=MOD($D22,18),1,0) -> 1 | M42: =INT($D22/18)+IF(M$6<=MOD($D22,18),1,0) -> 1 | ... W42: =INT($D22/18)+IF(W$6<=MOD($D22,18),1,0) -> 1
A45: Net score on each hole (gross minus strokes)
A46: =A8 -> Frank Barta | F46: =IF(ISNUMBER(F8),F8-F28,"") | G46: =IF(ISNUMBER(G8),G8-G28,"") | H46: =IF(ISNUMBER(H8),H8-H28,"") | I46: =IF(ISNUMBER(I8),I8-I28,"") | J46: =IF(ISNUMBER(J8),J8-J28,"") | K46: =IF(ISNUMBER(K8),K8-K28,"") | L46: =IF(ISNUMBER(L8),L8-L28,"") | M46: =IF(ISNUMBER(M8),M8-M28,"") | ... W46: =IF(ISNUMBER(W8),W8-W28,"")
A47: =A9 -> Marc Wydom | F47: =IF(ISNUMBER(F9),F9-F29,"") | G47: =IF(ISNUMBER(G9),G9-G29,"") | H47: =IF(ISNUMBER(H9),H9-H29,"") | I47: =IF(ISNUMBER(I9),I9-I29,"") | J47: =IF(ISNUMBER(J9),J9-J29,"") | K47: =IF(ISNUMBER(K9),K9-K29,"") | L47: =IF(ISNUMBER(L9),L9-L29,"") | M47: =IF(ISNUMBER(M9),M9-M29,"") | ... W47: =IF(ISNUMBER(W9),W9-W29,"")
...

Sheet R2 Palmer
A1: Round II · Arnold Palmer — Scorecard
A2: Friday, Nov 6 · Arnold Palmer · Gold · 70.9/133 tees · par 72
E4: Hole | F4: 1 | G4: 2 | H4: 3 | I4: 4 | J4: 5 | K4: 6 | L4: 7 | M4: 8 | N4: 9 | O4: 10 | P4: 11 | Q4: 12 | R4: 13 | S4: 14 | T4: 15 | U4: 16 | V4: 17 | W4: 18
E5: Par | F5: 4 | G5: 3 | H5: 5 | I5: 4 | J5: 3 | K5: 4 | L5: 4 | M5: 4 | N5: 5 | O5: 5 | P5: 4 | Q5: 4 | R5: 4 | S5: 3 | T5: 5 | U5: 3 | V5: 4 | W5: 4 | X5: =SUM(F5:W5) -> 72
E6: Hole hcp | F6: 5 | G6: 11 | H6: 9 | I6: 15 | J6: 13 | K6: 7 | L6: 17 | M6: 1 | N6: 3 | O6: 6 | P6: 14 | Q6: 8 | R6: 2 | S6: 18 | T6: 12 | U6: 16 | V6: 10 | W6: 4
A7: Player | B7: Team | C7: Hcp | D7: Strokes | E7: Group · Tee | F7: 1 | G7: 2 | H7: 3 | I7: 4 | J7: 5 | K7: 6 | L7: 7 | M7: 8 | N7: 9 | O7: 10 | P7: 11 | Q7: 12 | R7: 13 | S7: 14 | T7: 15 | U7: 16 | V7: 17 | W7: 18 | X7: Gross | Y7: Holes | Z7: Net | AA7: Mankles pts | AB7: Mankles round | AC7: Birdies+
A8: =Players!$A$5 -> Frank Barta | B8: =Players!$B$5 -> Team 2 | C8: =Players!$C$5 -> 8 | D8: =Players!$D$5 -> 0 | E8: Grp 3 · 11:10 AM | X8: =IF(COUNT(F8:W8)=0,"",SUM(F8:W8)) | Y8: =COUNT(F8:W8) -> 0 | Z8: =IF(COUNT(F8:W8)=0,"",SUM(F46:W46)) | AA8: =IF(COUNT(F8:W8)=0,"",SUM(F64:W64)) | AB8: =IF(COUNT(F8:W8)=0,"",C8+AA8) | AC8: =COUNTIF(F64:W64,">=4") -> 0
A9: =Players!$A$6 -> Marc Wydom | B9: =Players!$B$6 -> Team 2 | C9: =Players!$C$6 -> 16 | D9: =Players!$D$6 -> 8 | E9: Grp 2 · 11:00 AM | X9: =IF(COUNT(F9:W9)=0,"",SUM(F9:W9)) | Y9: =COUNT(F9:W9) -> 0 | Z9: =IF(COUNT(F9:W9)=0,"",SUM(F47:W47)) | AA9: =IF(COUNT(F9:W9)=0,"",SUM(F65:W65)) | AB9: =IF(COUNT(F9:W9)=0,"",C9+AA9) | AC9: =COUNTIF(F65:W65,">=4") -> 0
A10: =Players!$A$7 -> Donnie Muller | B10: =Players!$B$7 -> Team 2 | C10: =Players!$C$7 -> 19 | D10: =Players!$D$7 -> 11 | E10: Grp 4 · 11:20 AM | X10: =IF(COUNT(F10:W10)=0,"",SUM(F10:W10)) | Y10: =COUNT(F10:W10) -> 0 | Z10: =IF(COUNT(F10:W10)=0,"",SUM(F48:W48)) | AA10: =IF(COUNT(F10:W10)=0,"",SUM(F66:W66)) | AB10: =IF(COUNT(F10:W10)=0,"",C10+AA10) | AC10: =COUNTIF(F66:W66,">=4") -> 0
A11: =Players!$A$8 -> Tommy Duncan | B11: =Players!$B$8 -> Skull it and Pray | C11: =Players!$C$8 -> 24 | D11: =Players!$D$8 -> 16 | E11: Grp 1 · 10:50 AM | X11: =IF(COUNT(F11:W11)=0,"",SUM(F11:W11)) | Y11: =COUNT(F11:W11) -> 0 | Z11: =IF(COUNT(F11:W11)=0,"",SUM(F49:W49)) | AA11: =IF(COUNT(F11:W11)=0,"",SUM(F67:W67)) | AB11: =IF(COUNT(F11:W11)=0,"",C11+AA11) | AC11: =COUNTIF(F67:W67,">=4") -> 0
A12: =Players!$A$9 -> Jason Kimbo | B12: =Players!$B$9 -> Skull it and Pray | C12: =Players!$C$9 -> 17 | D12: =Players!$D$9 -> 9 | E12: Grp 4 · 11:20 AM | X12: =IF(COUNT(F12:W12)=0,"",SUM(F12:W12)) | Y12: =COUNT(F12:W12) -> 0 | Z12: =IF(COUNT(F12:W12)=0,"",SUM(F50:W50)) | AA12: =IF(COUNT(F12:W12)=0,"",SUM(F68:W68)) | AB12: =IF(COUNT(F12:W12)=0,"",C12+AA12) | AC12: =COUNTIF(F68:W68,">=4") -> 0
A13: =Players!$A$10 -> Spencer Friend | B13: =Players!$B$10 -> Skull it and Pray | C13: =Players!$C$10 -> 9 | D13: =Players!$D$10 -> 1 | E13: Grp 4 · 11:20 AM | X13: =IF(COUNT(F13:W13)=0,"",SUM(F13:W13)) | Y13: =COUNT(F13:W13) -> 0 | Z13: =IF(COUNT(F13:W13)=0,"",SUM(F51:W51)) | AA13: =IF(COUNT(F13:W13)=0,"",SUM(F69:W69)) | AB13: =IF(COUNT(F13:W13)=0,"",C13+AA13) | AC13: =COUNTIF(F69:W69,">=4") -> 0
A14: =Players!$A$11 -> Ben Young | B14: =Players!$B$11 -> Team 3 | C14: =Players!$C$11 -> 18 | D14: =Players!$D$11 -> 10 | E14: Grp 3 · 11:10 AM | X14: =IF(COUNT(F14:W14)=0,"",SUM(F14:W14)) | Y14: =COUNT(F14:W14) -> 0 | Z14: =IF(COUNT(F14:W14)=0,"",SUM(F52:W52)) | AA14: =IF(COUNT(F14:W14)=0,"",SUM(F70:W70)) | AB14: =IF(COUNT(F14:W14)=0,"",C14+AA14) | AC14: =COUNTIF(F70:W70,">=4") -> 0
A15: =Players!$A$12 -> Justin Conrad | B15: =Players!$B$12 -> Team 3 | C15: =Players!$C$12 -> 30 | D15: =Players!$D$12 -> 22 | E15: Grp 2 · 11:00 AM | X15: =IF(COUNT(F15:W15)=0,"",SUM(F15:W15)) | Y15: =COUNT(F15:W15) -> 0 | Z15: =IF(COUNT(F15:W15)=0,"",SUM(F53:W53)) | AA15: =IF(COUNT(F15:W15)=0,"",SUM(F71:W71)) | AB15: =IF(COUNT(F15:W15)=0,"",C15+AA15) | AC15: =COUNTIF(F71:W71,">=4") -> 0
A16: =Players!$A$13 -> Shawn McMaster | B16: =Players!$B$13 -> Team 3 | C16: =Players!$C$13 -> 19 | D16: =Players!$D$13 -> 11 | E16: Grp 1 · 10:50 AM | X16: =IF(COUNT(F16:W16)=0,"",SUM(F16:W16)) | Y16: =COUNT(F16:W16) -> 0 | Z16: =IF(COUNT(F16:W16)=0,"",SUM(F54:W54)) | AA16: =IF(COUNT(F16:W16)=0,"",SUM(F72:W72)) | AB16: =IF(COUNT(F16:W16)=0,"",C16+AA16) | AC16: =COUNTIF(F72:W72,">=4") -> 0
A17: =Players!$A$14 -> Ian Dempsey | B17: =Players!$B$14 -> Wydom’s Woodies | C17: =Players!$C$14 -> 21 | D17: =Players!$D$14 -> 13 | E17: Grp 3 · 11:10 AM | X17: =IF(COUNT(F17:W17)=0,"",SUM(F17:W17)) | Y17: =COUNT(F17:W17) -> 0 | Z17: =IF(COUNT(F17:W17)=0,"",SUM(F55:W55)) | AA17: =IF(COUNT(F17:W17)=0,"",SUM(F73:W73)) | AB17: =IF(COUNT(F17:W17)=0,"",C17+AA17) | AC17: =COUNTIF(F73:W73,">=4") -> 0
A18: =Players!$A$15 -> Nick Roy | B18: =Players!$B$15 -> Wydom’s Woodies | C18: =Players!$C$15 -> 21 | D18: =Players!$D$15 -> 13 | E18: Grp 4 · 11:20 AM | X18: =IF(COUNT(F18:W18)=0,"",SUM(F18:W18)) | Y18: =COUNT(F18:W18) -> 0 | Z18: =IF(COUNT(F18:W18)=0,"",SUM(F56:W56)) | AA18: =IF(COUNT(F18:W18)=0,"",SUM(F74:W74)) | AB18: =IF(COUNT(F18:W18)=0,"",C18+AA18) | AC18: =COUNTIF(F74:W74,">=4") -> 0
A19: =Players!$A$16 -> Henry Holst | B19: =Players!$B$16 -> Wydom’s Woodies | C19: =Players!$C$16 -> 19 | D19: =Players!$D$16 -> 11 | E19: Grp 2 · 11:00 AM | X19: =IF(COUNT(F19:W19)=0,"",SUM(F19:W19)) | Y19: =COUNT(F19:W19) -> 0 | Z19: =IF(COUNT(F19:W19)=0,"",SUM(F57:W57)) | AA19: =IF(COUNT(F19:W19)=0,"",SUM(F75:W75)) | AB19: =IF(COUNT(F19:W19)=0,"",C19+AA19) | AC19: =COUNTIF(F75:W75,">=4") -> 0
A20: =Players!$A$17 -> Chad Stone | B20: =Players!$B$17 -> Putting Balls in the Hole | C20: =Players!$C$17 -> 23 | D20: =Players!$D$17 -> 15 | E20: Grp 1 · 10:50 AM | X20: =IF(COUNT(F20:W20)=0,"",SUM(F20:W20)) | Y20: =COUNT(F20:W20) -> 0 | Z20: =IF(COUNT(F20:W20)=0,"",SUM(F58:W58)) | AA20: =IF(COUNT(F20:W20)=0,"",SUM(F76:W76)) | AB20: =IF(COUNT(F20:W20)=0,"",C20+AA20) | AC20: =COUNTIF(F76:W76,">=4") -> 0
A21: =Players!$A$18 -> Tom Devine | B21: =Players!$B$18 -> Putting Balls in the Hole | C21: =Players!$C$18 -> 17 | D21: =Players!$D$18 -> 9 | E21: Grp 2 · 11:00 AM | X21: =IF(COUNT(F21:W21)=0,"",SUM(F21:W21)) | Y21: =COUNT(F21:W21) -> 0 | Z21: =IF(COUNT(F21:W21)=0,"",SUM(F59:W59)) | AA21: =IF(COUNT(F21:W21)=0,"",SUM(F77:W77)) | AB21: =IF(COUNT(F21:W21)=0,"",C21+AA21) | AC21: =COUNTIF(F77:W77,">=4") -> 0
A22: =Players!$A$19 -> Mike Warenda | B22: =Players!$B$19 -> Putting Balls in the Hole | C22: =Players!$C$19 -> 21 | D22: =Players!$D$19 -> 13 | E22: Grp 3 · 11:10 AM | X22: =IF(COUNT(F22:W22)=0,"",SUM(F22:W22)) | Y22: =COUNT(F22:W22) -> 0 | Z22: =IF(COUNT(F22:W22)=0,"",SUM(F60:W60)) | AA22: =IF(COUNT(F22:W22)=0,"",SUM(F78:W78)) | AB22: =IF(COUNT(F22:W22)=0,"",C22+AA22) | AC22: =COUNTIF(F78:W78,">=4") -> 0
E24: Skin winner | F24: =IF(COUNT(F46:F60)<15,"",IF(COUNTIF(F46:F60,MIN(F46:F60))>1,"tie",INDEX($A$8:$A$22,MATCH(MIN(F46:F60),F46:F60,0)))) | G24: =IF(COUNT(G46:G60)<15,"",IF(COUNTIF(G46:G60,MIN(G46:G60))>1,"tie",INDEX($A$8:$A$22,MATCH(MIN(G46:G60),G46:G60,0)))) | H24: =IF(COUNT(H46:H60)<15,"",IF(COUNTIF(H46:H60,MIN(H46:H60))>1,"tie",INDEX($A$8:$A$22,MATCH(MIN(H46:H60),H46:H60,0)))) | I24: =IF(COUNT(I46:I60)<15,"",IF(COUNTIF(I46:I60,MIN(I46:I60))>1,"tie",INDEX($A$8:$A$22,MATCH(MIN(I46:I60),I46:I60,0)))) | J24: =IF(COUNT(J46:J60)<15,"",IF(COUNTIF(J46:J60,MIN(J46:J60))>1,"tie",INDEX($A$8:$A$22,MATCH(MIN(J46:J60),J46:J60,0)))) | K24: =IF(COUNT(K46:K60)<15,"",IF(COUNTIF(K46:K60,MIN(K46:K60))>1,"tie",INDEX($A$8:$A$22,MATCH(MIN(K46:K60),K46:K60,0)))) | L24: =IF(COUNT(L46:L60)<15,"",IF(COUNTIF(L46:L60,MIN(L46:L60))>1,"tie",INDEX($A$8:$A$22,MATCH(MIN(L46:L60),L46:L60,0)))) | M24: =IF(COUNT(M46:M60)<15,"",IF(COUNTIF(M46:M60,MIN(M46:M60))>1,"tie",INDEX($A$8:$A$22,MATCH(MIN(M46:M60),M46:M60,0)))) | ... W24: =IF(COUNT(W46:W60)<15,"",IF(COUNTIF(W46:W60,MIN(W46:W60))>1,"tie",INDEX($A$8:$A$22,MATCH(MIN(W46:W60),W46:W60,0))))
E25: Skins won | F25: =COUNTIF(F24:W24,"?*")-COUNTIF(F24:W24,"tie") -> 0 | H25: $ per skin | I25: =IF(F25=0,0,Leaderboard!$B$3/F25) -> 0
A27: Handicap strokes on each hole (automatic)
A28: =A8 -> Frank Barta | F28: =INT($D8/18)+IF(F$6<=MOD($D8,18),1,0) -> 0 | G28: =INT($D8/18)+IF(G$6<=MOD($D8,18),1,0) -> 0 | H28: =INT($D8/18)+IF(H$6<=MOD($D8,18),1,0) -> 0 | I28: =INT($D8/18)+IF(I$6<=MOD($D8,18),1,0) -> 0 | J28: =INT($D8/18)+IF(J$6<=MOD($D8,18),1,0) -> 0 | K28: =INT($D8/18)+IF(K$6<=MOD($D8,18),1,0) -> 0 | L28: =INT($D8/18)+IF(L$6<=MOD($D8,18),1,0) -> 0 | M28: =INT($D8/18)+IF(M$6<=MOD($D8,18),1,0) -> 0 | ... W28: =INT($D8/18)+IF(W$6<=MOD($D8,18),1,0) -> 0
A29: =A9 -> Marc Wydom | F29: =INT($D9/18)+IF(F$6<=MOD($D9,18),1,0) -> 1 | G29: =INT($D9/18)+IF(G$6<=MOD($D9,18),1,0) -> 0 | H29: =INT($D9/18)+IF(H$6<=MOD($D9,18),1,0) -> 0 | I29: =INT($D9/18)+IF(I$6<=MOD($D9,18),1,0) -> 0 | J29: =INT($D9/18)+IF(J$6<=MOD($D9,18),1,0) -> 0 | K29: =INT($D9/18)+IF(K$6<=MOD($D9,18),1,0) -> 1 | L29: =INT($D9/18)+IF(L$6<=MOD($D9,18),1,0) -> 0 | M29: =INT($D9/18)+IF(M$6<=MOD($D9,18),1,0) -> 1 | ... W29: =INT($D9/18)+IF(W$6<=MOD($D9,18),1,0) -> 1
A30: =A10 -> Donnie Muller | F30: =INT($D10/18)+IF(F$6<=MOD($D10,18),1,0) -> 1 | G30: =INT($D10/18)+IF(G$6<=MOD($D10,18),1,0) -> 1 | H30: =INT($D10/18)+IF(H$6<=MOD($D10,18),1,0) -> 1 | I30: =INT($D10/18)+IF(I$6<=MOD($D10,18),1,0) -> 0 | J30: =INT($D10/18)+IF(J$6<=MOD($D10,18),1,0) -> 0 | K30: =INT($D10/18)+IF(K$6<=MOD($D10,18),1,0) -> 1 | L30: =INT($D10/18)+IF(L$6<=MOD($D10,18),1,0) -> 0 | M30: =INT($D10/18)+IF(M$6<=MOD($D10,18),1,0) -> 1 | ... W30: =INT($D10/18)+IF(W$6<=MOD($D10,18),1,0) -> 1
A31: =A11 -> Tommy Duncan | F31: =INT($D11/18)+IF(F$6<=MOD($D11,18),1,0) -> 1 | G31: =INT($D11/18)+IF(G$6<=MOD($D11,18),1,0) -> 1 | H31: =INT($D11/18)+IF(H$6<=MOD($D11,18),1,0) -> 1 | I31: =INT($D11/18)+IF(I$6<=MOD($D11,18),1,0) -> 1 | J31: =INT($D11/18)+IF(J$6<=MOD($D11,18),1,0) -> 1 | K31: =INT($D11/18)+IF(K$6<=MOD($D11,18),1,0) -> 1 | L31: =INT($D11/18)+IF(L$6<=MOD($D11,18),1,0) -> 0 | M31: =INT($D11/18)+IF(M$6<=MOD($D11,18),1,0) -> 1 | ... W31: =INT($D11/18)+IF(W$6<=MOD($D11,18),1,0) -> 1
A32: =A12 -> Jason Kimbo | F32: =INT($D12/18)+IF(F$6<=MOD($D12,18),1,0) -> 1 | G32: =INT($D12/18)+IF(G$6<=MOD($D12,18),1,0) -> 0 | H32: =INT($D12/18)+IF(H$6<=MOD($D12,18),1,0) -> 1 | I32: =INT($D12/18)+IF(I$6<=MOD($D12,18),1,0) -> 0 | J32: =INT($D12/18)+IF(J$6<=MOD($D12,18),1,0) -> 0 | K32: =INT($D12/18)+IF(K$6<=MOD($D12,18),1,0) -> 1 | L32: =INT($D12/18)+IF(L$6<=MOD($D12,18),1,0) -> 0 | M32: =INT($D12/18)+IF(M$6<=MOD($D12,18),1,0) -> 1 | ... W32: =INT($D12/18)+IF(W$6<=MOD($D12,18),1,0) -> 1
A33: =A13 -> Spencer Friend | F33: =INT($D13/18)+IF(F$6<=MOD($D13,18),1,0) -> 0 | G33: =INT($D13/18)+IF(G$6<=MOD($D13,18),1,0) -> 0 | H33: =INT($D13/18)+IF(H$6<=MOD($D13,18),1,0) -> 0 | I33: =INT($D13/18)+IF(I$6<=MOD($D13,18),1,0) -> 0 | J33: =INT($D13/18)+IF(J$6<=MOD($D13,18),1,0) -> 0 | K33: =INT($D13/18)+IF(K$6<=MOD($D13,18),1,0) -> 0 | L33: =INT($D13/18)+IF(L$6<=MOD($D13,18),1,0) -> 0 | M33: =INT($D13/18)+IF(M$6<=MOD($D13,18),1,0) -> 1 | ... W33: =INT($D13/18)+IF(W$6<=MOD($D13,18),1,0) -> 0
A34: =A14 -> Ben Young | F34: =INT($D14/18)+IF(F$6<=MOD($D14,18),1,0) -> 1 | G34: =INT($D14/18)+IF(G$6<=MOD($D14,18),1,0) -> 0 | H34: =INT($D14/18)+IF(H$6<=MOD($D14,18),1,0) -> 1 | I34: =INT($D14/18)+IF(I$6<=MOD($D14,18),1,0) -> 0 | J34: =INT($D14/18)+IF(J$6<=MOD($D14,18),1,0) -> 0 | K34: =INT($D14/18)+IF(K$6<=MOD($D14,18),1,0) -> 1 | L34: =INT($D14/18)+IF(L$6<=MOD($D14,18),1,0) -> 0 | M34: =INT($D14/18)+IF(M$6<=MOD($D14,18),1,0) -> 1 | ... W34: =INT($D14/18)+IF(W$6<=MOD($D14,18),1,0) -> 1
A35: =A15 -> Justin Conrad | F35: =INT($D15/18)+IF(F$6<=MOD($D15,18),1,0) -> 1 | G35: =INT($D15/18)+IF(G$6<=MOD($D15,18),1,0) -> 1 | H35: =INT($D15/18)+IF(H$6<=MOD($D15,18),1,0) -> 1 | I35: =INT($D15/18)+IF(I$6<=MOD($D15,18),1,0) -> 1 | J35: =INT($D15/18)+IF(J$6<=MOD($D15,18),1,0) -> 1 | K35: =INT($D15/18)+IF(K$6<=MOD($D15,18),1,0) -> 1 | L35: =INT($D15/18)+IF(L$6<=MOD($D15,18),1,0) -> 1 | M35: =INT($D15/18)+IF(M$6<=MOD($D15,18),1,0) -> 2 | ... W35: =INT($D15/18)+IF(W$6<=MOD($D15,18),1,0) -> 2
A36: =A16 -> Shawn McMaster | F36: =INT($D16/18)+IF(F$6<=MOD($D16,18),1,0) -> 1 | G36: =INT($D16/18)+IF(G$6<=MOD($D16,18),1,0) -> 1 | H36: =INT($D16/18)+IF(H$6<=MOD($D16,18),1,0) -> 1 | I36: =INT($D16/18)+IF(I$6<=MOD($D16,18),1,0) -> 0 | J36: =INT($D16/18)+IF(J$6<=MOD($D16,18),1,0) -> 0 | K36: =INT($D16/18)+IF(K$6<=MOD($D16,18),1,0) -> 1 | L36: =INT($D16/18)+IF(L$6<=MOD($D16,18),1,0) -> 0 | M36: =INT($D16/18)+IF(M$6<=MOD($D16,18),1,0) -> 1 | ... W36: =INT($D16/18)+IF(W$6<=MOD($D16,18),1,0) -> 1
A37: =A17 -> Ian Dempsey | F37: =INT($D17/18)+IF(F$6<=MOD($D17,18),1,0) -> 1 | G37: =INT($D17/18)+IF(G$6<=MOD($D17,18),1,0) -> 1 | H37: =INT($D17/18)+IF(H$6<=MOD($D17,18),1,0) -> 1 | I37: =INT($D17/18)+IF(I$6<=MOD($D17,18),1,0) -> 0 | J37: =INT($D17/18)+IF(J$6<=MOD($D17,18),1,0) -> 1 | K37: =INT($D17/18)+IF(K$6<=MOD($D17,18),1,0) -> 1 | L37: =INT($D17/18)+IF(L$6<=MOD($D17,18),1,0) -> 0 | M37: =INT($D17/18)+IF(M$6<=MOD($D17,18),1,0) -> 1 | ... W37: =INT($D17/18)+IF(W$6<=MOD($D17,18),1,0) -> 1
A38: =A18 -> Nick Roy | F38: =INT($D18/18)+IF(F$6<=MOD($D18,18),1,0) -> 1 | G38: =INT($D18/18)+IF(G$6<=MOD($D18,18),1,0) -> 1 | H38: =INT($D18/18)+IF(H$6<=MOD($D18,18),1,0) -> 1 | I38: =INT($D18/18)+IF(I$6<=MOD($D18,18),1,0) -> 0 | J38: =INT($D18/18)+IF(J$6<=MOD($D18,18),1,0) -> 1 | K38: =INT($D18/18)+IF(K$6<=MOD($D18,18),1,0) -> 1 | L38: =INT($D18/18)+IF(L$6<=MOD($D18,18),1,0) -> 0 | M38: =INT($D18/18)+IF(M$6<=MOD($D18,18),1,0) -> 1 | ... W38: =INT($D18/18)+IF(W$6<=MOD($D18,18),1,0) -> 1
A39: =A19 -> Henry Holst | F39: =INT($D19/18)+IF(F$6<=MOD($D19,18),1,0) -> 1 | G39: =INT($D19/18)+IF(G$6<=MOD($D19,18),1,0) -> 1 | H39: =INT($D19/18)+IF(H$6<=MOD($D19,18),1,0) -> 1 | I39: =INT($D19/18)+IF(I$6<=MOD($D19,18),1,0) -> 0 | J39: =INT($D19/18)+IF(J$6<=MOD($D19,18),1,0) -> 0 | K39: =INT($D19/18)+IF(K$6<=MOD($D19,18),1,0) -> 1 | L39: =INT($D19/18)+IF(L$6<=MOD($D19,18),1,0) -> 0 | M39: =INT($D19/18)+IF(M$6<=MOD($D19,18),1,0) -> 1 | ... W39: =INT($D19/18)+IF(W$6<=MOD($D19,18),1,0) -> 1
... A42: =A22 -> Mike Warenda | F42: =INT($D22/18)+IF(F$6<=MOD($D22,18),1,0) -> 1 | G42: =INT($D22/18)+IF(G$6<=MOD($D22,18),1,0) -> 1 | H42: =INT($D22/18)+IF(H$6<=MOD($D22,18),1,0) -> 1 | I42: =INT($D22/18)+IF(I$6<=MOD($D22,18),1,0) -> 0 | J42: =INT($D22/18)+IF(J$6<=MOD($D22,18),1,0) -> 1 | K42: =INT($D22/18)+IF(K$6<=MOD($D22,18),1,0) -> 1 | L42: =INT($D22/18)+IF(L$6<=MOD($D22,18),1,0) -> 0 | M42: =INT($D22/18)+IF(M$6<=MOD($D22,18),1,0) -> 1 | ... W42: =INT($D22/18)+IF(W$6<=MOD($D22,18),1,0) -> 1
A45: Net score on each hole (gross minus strokes)
A46: =A8 -> Frank Barta | F46: =IF(ISNUMBER(F8),F8-F28,"") | G46: =IF(ISNUMBER(G8),G8-G28,"") | H46: =IF(ISNUMBER(H8),H8-H28,"") | I46: =IF(ISNUMBER(I8),I8-I28,"") | J46: =IF(ISNUMBER(J8),J8-J28,"") | K46: =IF(ISNUMBER(K8),K8-K28,"") | L46: =IF(ISNUMBER(L8),L8-L28,"") | M46: =IF(ISNUMBER(M8),M8-M28,"") | ... W46: =IF(ISNUMBER(W8),W8-W28,"")
A47: =A9 -> Marc Wydom | F47: =IF(ISNUMBER(F9),F9-F29,"") | G47: =IF(ISNUMBER(G9),G9-G29,"") | H47: =IF(ISNUMBER(H9),H9-H29,"") | I47: =IF(ISNUMBER(I9),I9-I29,"") | J47: =IF(ISNUMBER(J9),J9-J29,"") | K47: =IF(ISNUMBER(K9),K9-K29,"") | L47: =IF(ISNUMBER(L9),L9-L29,"") | M47: =IF(ISNUMBER(M9),M9-M29,"") | ... W47: =IF(ISNUMBER(W9),W9-W29,"")
...

Sheet R3 Nicklaus
A1: Round III · Jack Nicklaus — Scorecard
A2: Saturday, Nov 7 · Jack Nicklaus · Blue tees · par 72
E4: Hole | F4: 1 | G4: 2 | H4: 3 | I4: 4 | J4: 5 | K4: 6 | L4: 7 | M4: 8 | N4: 9 | O4: 10 | P4: 11 | Q4: 12 | R4: 13 | S4: 14 | T4: 15 | U4: 16 | V4: 17 | W4: 18
E5: Par | F5: 4 | G5: 4 | H5: 5 | I5: 4 | J5: 3 | K5: 5 | L5: 4 | M5: 3 | N5: 4 | O5: 4 | P5: 3 | Q5: 4 | R5: 4 | S5: 4 | T5: 5 | U5: 3 | V5: 4 | W5: 5 | X5: =SUM(F5:W5) -> 72
E6: Hole hcp | F6: 17 | G6: 1 | H6: 5 | I6: 3 | J6: 7 | K6: 13 | L6: 9 | M6: 15 | N6: 11 | O6: 4 | P6: 18 | Q6: 6 | R6: 10 | S6: 2 | T6: 12 | U6: 8 | V6: 14 | W6: 16
A7: Player | B7: Team | C7: Hcp | D7: Strokes | E7: Group · Tee | F7: 1 | G7: 2 | H7: 3 | I7: 4 | J7: 5 | K7: 6 | L7: 7 | M7: 8 | N7: 9 | O7: 10 | P7: 11 | Q7: 12 | R7: 13 | S7: 14 | T7: 15 | U7: 16 | V7: 17 | W7: 18 | X7: Gross | Y7: Holes | Z7: Net | AA7: Mankles pts | AB7: Mankles round | AC7: Birdies+ | AD7: Net place | AE7: Team pts
A8: =Players!$A$5 -> Frank Barta | B8: =Players!$B$5 -> Team 2 | C8: =Players!$C$5 -> 8 | D8: =Players!$D$5 -> 0 | X8: =IF(COUNT(F8:W8)=0,"",SUM(F8:W8)) | Y8: =COUNT(F8:W8) -> 0 | Z8: =IF(COUNT(F8:W8)=0,"",SUM(F46:W46)) | AA8: =IF(COUNT(F8:W8)=0,"",SUM(F64:W64)) | AB8: =IF(COUNT(F8:W8)=0,"",C8+AA8) | AC8: =COUNTIF(F64:W64,">=4") -> 0 | AD8: =IF(AF8="","",COUNTIF($AF$8:$AF$22,"<"&AF8)+1) | AE8: =IF(AF8="","",COUNTA($A$8:$A$22)+1-AD8-(COUNTIF($AF$8:$AF$22,AF8)-1)/2) | AF8: =IF(Y8=18,Z8,"")
A9: =Players!$A$6 -> Marc Wydom | B9: =Players!$B$6 -> Team 2 | C9: =Players!$C$6 -> 16 | D9: =Players!$D$6 -> 8 | X9: =IF(COUNT(F9:W9)=0,"",SUM(F9:W9)) | Y9: =COUNT(F9:W9) -> 0 | Z9: =IF(COUNT(F9:W9)=0,"",SUM(F47:W47)) | AA9: =IF(COUNT(F9:W9)=0,"",SUM(F65:W65)) | AB9: =IF(COUNT(F9:W9)=0,"",C9+AA9) | AC9: =COUNTIF(F65:W65,">=4") -> 0 | AD9: =IF(AF9="","",COUNTIF($AF$8:$AF$22,"<"&AF9)+1) | AE9: =IF(AF9="","",COUNTA($A$8:$A$22)+1-AD9-(COUNTIF($AF$8:$AF$22,AF9)-1)/2) | AF9: =IF(Y9=18,Z9,"")
